Workbook

Sheet 总览
A2: NYC 311 服务请求看板
A4: 全量覆盖 2024-09-07 至 2026-09-05；主要比较 2025 与 2026 年 1—8 月。单位：请求记录。
A6: 核心指标 | B6: 2025年1—8月 | C6: 2026年1—8月 | D6: 增加记录 | E6: 同比增幅
A7: 请求记录量 | B7: =月度趋势!B14 -> 2378736 | C7: =月度趋势!C14 -> 2666078 | D7: =月度趋势!D14 -> 287342 | E7: =月度趋势!E14 -> 0.12079609
A9: 1 增长有集中来源，也有广泛基础
A10: 道路、雪冰、供暖合计贡献47.6%的净增量；排除这三类后，其余请求仍增长7.0%。
A12: 2 雪冰尖峰与道路持续增长需要分别看待
A13: 雪冰最高5天占59.4%；道路8个月中7个月上升，坑洞贡献道路净增量的74.0%。
A15: 3 ONLINE 记录占比上升，固定构成后仍成立
A16: 实际占比 42.5% → 48.2%；固定月份、类别、机构构成后提高6.74个百分点。
A34: 使用边界
A35: 请求记录不等于独立事件或居民数。数据无法证明天气原因、用户迁移或服务绩效变化。
A36: 首尾不完整月份不参与同比；状态与关闭日期存在不一致，近期结案时长受观察期截断影响。
A39: 月度趋势 | C39: 同比拆解 | E39: 峰值核查 | G39: 渠道变化 | I39: 数据质量 | K39: 口径与复现

Sheet 月度趋势
A2: 请求量增长是否持续？
A4: 同比主窗：两年各 1 月 1 日至 9 月 1 日前，均为 243 天；单位：请求记录。
A5: 月份 | B5: 2025年记录 | C5: 2026年记录 | D5: 增加记录 | E5: 同比增幅 | H5: 敏感性检查 | I5: 2025记录 | J5: 2026记录 | K5: 增加记录 | L5: 同比增幅
A6: 1 | B6: 348180 | C6: 348511 | D6: =C6-B6 -> 331 | E6: =D6/B6 -> 0.00095065771 | H6: 全量 | I6: 2378736 | J6: 2666078 | K6: =J6-I6 -> 287342 | L6: =K6/I6 -> 0.12079609
A7: 2 | B7: 255364 | C7: 334690 | D7: =C7-B7 -> 79326 | E7: =D7/B7 -> 0.31063893 | H7: 排除雪冰与道路 | I7: 2319535 | J7: 2511928 | K7: =J7-I7 -> 192393 | L7: =K7/I7 -> 0.082944642
A8: 3 | B8: 281221 | C8: 342387 | D8: =C8-B8 -> 61166 | E8: =D8/B8 -> 0.21750154 | H8: 排除雪冰、道路与供暖 | I8: 2150890 | J8: 2301409 | K8: =J8-I8 -> 150519 | L8: =K8/I8 -> 0.069979869
A9: 4 | B9: 272549 | C9: 302190 | D9: =C9-B9 -> 29641 | E9: =D9/B9 -> 0.10875476 | H9: 只看4—8月 | I9: 1493971 | J9: 1640490 | K9: =J9-I9 -> 146519 | L9: =K9/I9 -> 0.098073524
A10: 5 | B10: 295058 | C10: 331978 | D10: =C10-B10 -> 36920 | E10: =D10/B10 -> 0.12512794
A11: 6 | B11: 306442 | C11: 334833 | D11: =C11-B11 -> 28391 | E11: =D11/B11 -> 0.092647222
A12: 7 | B12: 315883 | C12: 343043 | D12: =C12-B12 -> 27160 | E12: =D12/B12 -> 0.085981202 | H12: 同一排除规则应用于两年；仍保留全部状态和渠道。
A13: 8 | B13: 304039 | C13: 328446 | D13: =C13-B13 -> 24407 | E13: =D13/B13 -> 0.080275886
A14: 1—8月合计 | B14: =SUM(B6:B13) -> 2378736 | C14: =SUM(C6:C13) -> 2666078 | D14: =SUM(D6:D13) -> 287342 | E14: =D14/B14 -> 0.12079609
A17: 全量覆盖：首尾月份只展示，不纳入完整月份同比
A19: 创建月份 | B19: 记录数 | C19: 有记录天数 | D19: 该月最早时间 | E19: 该月最晚时间 | F19: 覆盖判断
A20: 45536 | B20: 248139 | C20: 24 | D20: 2024-09-07 00:00:00 | E20: 2024-09-30 23:59:31 | F20: 部分月份
A21: 45566 | B21: 306803 | C21: 31 | D21: 2024-10-01 00:00:00 | E21: 2024-10-31 23:59:46 | F21: 日历日齐全
A22: 45597 | B22: 293515 | C22: 30 | D22: 2024-11-01 00:00:06 | E22: 2024-11-30 23:59:46 | F22: 日历日齐全
A23: 45627 | B23: 313949 | C23: 31 | D23: 2024-12-01 00:00:03 | E23: 2024-12-31 23:59:38 | F23: 日历日齐全
A24: 45658 | B24: 348180 | C24: 31 | D24: 2025-01-01 00:00:12 | E24: 2025-01-31 23:59:48 | F24: 日历日齐全
A25: 45689 | B25: 255364 | C25: 28 | D25: 2025-02-01 00:00:00 | E25: 2025-02-28 23:59:48 | F25: 日历日齐全
A26: 45717 | B26: 281221 | C26: 31 | D26: 2025-03-01 00:00:08 | E26: 2025-03-31 23:59:57 | F26: 日历日齐全
A27: 45748 | B27: 272549 | C27: 30 | D27: 2025-04-01 00:00:00 | E27: 2025-04-30 23:59:55 | F27: 日历日齐全
A28: 45778 | B28: 295058 | C28: 31 | D28: 2025-05-01 00:00:02 | E28: 2025-05-31 23:59:54 | F28: 日历日齐全
A29: 45809 | B29: 306442 | C29: 30 | D29: 2025-06-01 00:00:05 | E29: 2025-06-30 23:59:46 | F29: 日历日齐全
A30: 45839 | B30: 315883 | C30: 31 | D30: 2025-07-01 00:00:23 | E30: 2025-07-31 23:59:58 | F30: 日历日齐全
A31: 45870 | B31: 304039 | C31: 31 | D31: 2025-08-01 00:00:00 | E31: 2025-08-31 23:59:56 | F31: 日历日齐全
... A44: 46266 | B44: 41974 | C44: 5 | D44: 2026-09-01 00:00:05 | E44: 2026-09-05 01:50:33 | F44: 部分月份
A46: 合计 | B46: =SUM(B20:B44) -> 7525498

Sheet 同比拆解
A2: 哪些类别与机构贡献了增量？
A4: 2026年1—8月 对比 2025年同期；贡献率 = 类别增量 / 全部净增量 287,342。负贡献会抵消增长。
A5: 原始请求类别 | B5: 2025年记录 | C5: 2026年记录 | D5: 增加记录 | E5: 同比增幅 | F5: 净增量贡献 | H5: 机构 | I5: 2025年 | J5: 2026年 | K5: 增加记录 | L5: 贡献率
A6: Street Condition | B6: 51211 | C6: 98920 | D6: =C6-B6 -> 47709 | E6: =IF(B6=0,"无基期",D6/B6) -> 0.93161625 | F6: =D6/月度趋势!$D$14 -> 0.1660356 | H6: HPD | I6: 465237 | J6: 581352 | K6: =J6-I6 -> 116115 | L6: =K6/月度趋势!$D$14 -> 0.40410034
A7: Snow or Ice | B7: 7990 | C7: 55230 | D7: =C7-B7 -> 47240 | E7: =IF(B7=0,"无基期",D7/B7) -> 5.9123905 | F7: =D7/月度趋势!$D$14 -> 0.16440339 | H7: DOT | I7: 146384 | J7: 210945 | K7: =J7-I7 -> 64561 | L7: =K7/月度趋势!$D$14 -> 0.22468348
A8: HEAT/HOT WATER | B8: 168645 | C8: 210519 | D8: =C8-B8 -> 41874 | E8: =IF(B8=0,"无基期",D8/B8) -> 0.24829672 | F8: =D8/月度趋势!$D$14 -> 0.14572878 | H8: DSNY | I8: 224037 | J8: 257553 | K8: =J8-I8 -> 33516 | L8: =K8/月度趋势!$D$14 -> 0.11664149
A9: Illegal Parking | B9: 380337 | C9: 415399 | D9: =C9-B9 -> 35062 | E9: =IF(B9=0,"无基期",D9/B9) -> 0.092186666 | F9: =D9/月度趋势!$D$14 -> 0.12202184 | H9: DPR | I9: 76607 | J9: 99558 | K9: =J9-I9 -> 22951 | L9: =K9/月度趋势!$D$14 -> 0.079873461
A10: Blocked Driveway | B10: 109480 | C10: 130461 | D10: =C10-B10 -> 20981 | E10: =IF(B10=0,"无基期",D10/B10) -> 0.19164231 | F10: =D10/月度趋势!$D$14 -> 0.073017519 | H10: DEP | I10: 137483 | J10: 157856 | K10: =J10-I10 -> 20373 | L10: =K10/月度趋势!$D$14 -> 0.070901574
A11: UNSANITARY CONDITION | B11: 75585 | C11: 91605 | D11: =C11-B11 -> 16020 | E11: =IF(B11=0,"无基期",D11/B11) -> 0.21194681 | F11: =D11/月度趋势!$D$14 -> 0.055752379 | H11: NYPD | I11: 1119122 | J11: 1136571 | K11: =J11-I11 -> 17449 | L11: =K11/月度趋势!$D$14 -> 0.060725547
A12: PLUMBING | B12: 45429 | C12: 58930 | D12: =C12-B12 -> 13501 | E12: =IF(B12=0,"无基期",D12/B12) -> 0.29718902 | F12: =D12/月度趋势!$D$14 -> 0.046985822 | H12: DOB | I12: 66971 | J12: 81823 | K12: =J12-I12 -> 14852 | L12: =K12/月度趋势!$D$14 -> 0.051687536
A13: Damaged Tree | B13: 19794 | C13: 32265 | D13: =C13-B13 -> 12471 | E13: =IF(B13=0,"无基期",D13/B13) -> 0.63003941 | F13: =D13/月度趋势!$D$14 -> 0.043401243 | H13: OOS | I13: 0 | J13: 3015 | K13: =J13-I13 -> 3015 | L13: =K13/月度趋势!$D$14 -> 0.010492723
A14: Water Maintenance | B14: 7 | C14: 11284 | D14: =C14-B14 -> 11277 | E14: =IF(B14=0,"无基期",D14/B14) -> 1611 | F14: =D14/月度趋势!$D$14 -> 0.039245916 | H14: TLC | I14: 22949 | J14: 25679 | K14: =J14-I14 -> 2730 | L14: =K14/月度趋势!$D$14 -> 0.0095008735
A15: Traffic Signal Condition | B15: 34208 | C15: 43417 | D15: =C15-B15 -> 9209 | E15: =IF(B15=0,"无基期",D15/B15) -> 0.26920603 | F15: =D15/月度趋势!$D$14 -> 0.032048917 | H15: DCWP | I15: 12313 | J15: 14323 | K15: =J15-I15 -> 2010 | L15: =K15/月度趋势!$D$14 -> 0.0069951486
A16: GENERAL | B16: 21191 | C16: 29848 | D16: =C16-B16 -> 8657 | E16: =IF(B16=0,"无基期",D16/B16) -> 0.40852249 | F16: =D16/月度趋势!$D$14 -> 0.030127862 | H16: NYC311-PRD | I16: 0 | J16: 371 | K16: =J16-I16 -> 371 | L16: =K16/月度趋势!$D$14 -> 0.0012911444
A17: WATER LEAK | B17: 24817 | C17: 32874 | D17: =C17-B17 -> 8057 | E17: =IF(B17=0,"无基期",D17/B17) -> 0.32465649 | F17: =D17/月度趋势!$D$14 -> 0.028039758 | H17: OTI | I17: 152 | J17: 195 | K17: =J17-I17 -> 43 | L17: =K17/月度趋势!$D$14 -> 0.00014964746
... A21: DOOR/WINDOW | B21: 29113 | C21: 35969 | D21: =C21-B21 -> 6856 | E21: =IF(B21=0,"无基期",D21/B21) -> 0.23549617 | F21: =D21/月度趋势!$D$14 -> 0.023860069 | H21: EDC | I21: 13257 | J21: 6994 | K21: =J21-I21 -> -6263 | L21: =K21/月度趋势!$D$14 -> -0.021796326
A22: Sewer Maintenance | B22: 8 | C22: 6588 | D22: =C22-B22 -> 6580 | E22: =IF(B22=0,"无基期",D22/B22) -> 822.5 | F22: =D22/月度趋势!$D$14 -> 0.022899541
A23: Building/Use | B23: 13789 | C23: 18673 | D23: =C23-B23 -> 4884 | E23: =IF(B23=0,"无基期",D23/B23) -> 0.35419537 | F23: =D23/月度趋势!$D$14 -> 0.016997167
A24: ELECTRIC | B24: 20087 | C24: 24520 | D24: =C24-B24 -> 4433 | E24: =IF(B24=0,"无基期",D24/B24) -> 0.22069 | F24: =D24/月度趋势!$D$14 -> 0.015427609
A25: Maintenance or Facility | B25: 16999 | C25: 21081 | D25: =C25-B25 -> 4082 | E25: =IF(B25=0,"无基期",D25/B25) -> 0.24013177 | F25: =D25/月度趋势!$D$14 -> 0.014206068
A26: General Construction/Plumbing | B26: 23581 | C26: 27525 | D26: =C26-B26 -> 3944 | E26: =IF(B26=0,"无基期",D26/B26) -> 0.1672533 | F26: =D26/月度趋势!$D$14 -> 0.013725804 | H26: 行政区 | I26: 2025年 | J26: 2026年 | K26: 增加记录 | L26: 贡献率
A27: FLOORING/STAIRS | B27: 17261 | C27: 21102 | D27: =C27-B27 -> 3841 | E27: =IF(B27=0,"无基期",D27/B27) -> 0.22252477 | F27: =D27/月度趋势!$D$14 -> 0.013367346 | H27: BROOKLYN | I27: 707179 | J27: 826230 | K27: =J27-I27 -> 119051 | L27: =K27/月度趋势!$D$14 -> 0.41431813
A28: Elevator | B28: 14590 | C28: 18398 | D28: =C28-B28 -> 3808 | E28: =IF(B28=0,"无基期",D28/B28) -> 0.26100069 | F28: =D28/月度趋势!$D$14 -> 0.013252501 | H28: QUEENS | I28: 582765 | J28: 669228 | K28: =J28-I28 -> 86463 | L28: =K28/月度趋势!$D$14 -> 0.30090624
A29: Noise | B29: 36082 | C29: 39588 | D29: =C29-B29 -> 3506 | E29: =IF(B29=0,"无基期",D29/B29) -> 0.097167563 | F29: =D29/月度趋势!$D$14 -> 0.012201488 | H29: MANHATTAN | I29: 470739 | J29: 511268 | K29: =J29-I29 -> 40529 | L29: =K29/月度趋势!$D$14 -> 0.14104795
A30: Overgrown Tree/Branches | B30: 13405 | C30: 16794 | D30: =C30-B30 -> 3389 | E30: =IF(B30=0,"无基期",D30/B30) -> 0.25281611 | F30: =D30/月度趋势!$D$14 -> 0.011794308 | H30: STATEN ISLAND | I30: 90416 | J30: 115849 | K30: =J30-I30 -> 25433 | L30: =K30/月度趋势!$D$14 -> 0.088511251
A31: Street Light Condition | B31: 20685 | C31: 23886 | D31: =C31-B31 -> 3201 | E31: =IF(B31=0,"无基期",D31/B31) -> 0.15474982 | F31: =D31/月度趋势!$D$14 -> 0.011140035 | H31: BRONX | I31: 525895 | J31: 540643 | K31: =J31-I31 -> 14748 | L31: =K31/月度趋势!$D$14 -> 0.051325598
A32: Cannabis Retailer | B32: 0 | C32: 3015 | D32: =C32-B32 -> 3015 | E32: =IF(B32=0,"无基期",D32/B32) -> 无基期 | F32: =D32/月度趋势!$D$14 -> 0.010492723 | H32: Unspecified | I32: 1742 | J32: 2860 | K32: =J32-I32 -> 1118 | L32: =K32/月度趋势!$D$14 -> 0.0038908339
A33: APPLIANCE | B33: 14455 | C33: 17314 | D33: =C33-B33 -> 2859 | E33: =IF(B33=0,"无基期",D33/B33) -> 0.19778623 | F33: =D33/月度趋势!$D$14 -> 0.0099498159
A34: Abandoned Vehicle | B34: 47387 | C34: 50044 | D34: =C34-B34 -> 2657 | E34: =IF(B34=0,"无基期",D34/B34) -> 0.05607023 | F34: =D34/月度趋势!$D$14 -> 0.0092468209
A35: Highway Condition | B35: 2688 | C35: 5225 | D35: =C35-B35 -> 2537 | E35: =IF(B35=0,"无基期",D35/B35) -> 0.9438244 | F35: =D35/月度趋势!$D$14 -> 0.0088292 | H35: 行政区比较未按人口归一化。
A36: Water Conservation | B36: 2978 | C36: 5476 | D36: =C36-B36 -> 2498 | E36: =IF(B36=0,"无基期",D36/B36) -> 0.838818 | F36: =D36/月度趋势!$D$14 -> 0.0086934733
A37: Sewer | B37: 16529 | C37: 18776 | D37: =C37-B37 -> 2247 | E37: =IF(B37=0,"无基期",D37/B37) -> 0.13594289 | F37: =D37/月度趋势!$D$14 -> 0.0078199497 | H37: 机构、类别、行政区是独立拆解，不可跨表相加。
A38: Noise - Street/Sidewalk | B38: 122920 | C38: 124971 | D38: =C38-B38 -> 2051 | E38: =IF(B38=0,"无基期",D38/B38) -> 0.016685649 | F38: =D38/月度趋势!$D$14 -> 0.0071378357
A39: Consumer Complaint | B39: 12313 | C39: 14323 | D39: =C39-B39 -> 2010 | E39: =IF(B39=0,"无基期",D39/B39) -> 0.1632421 | F39: =D39/月度趋势!$D$14 -> 0.0069951486
A40: Indoor Air Quality | B40: 5653 | C40: 7475 | D40: =C40-B40 -> 1822 | E40: =IF(B40=0,"无基期",D40/B40) -> 0.32230674 | F40: =D40/月度趋势!$D$14 -> 0.006340876
A41: Smoking or Vaping | B41: 3831 | C41: 5631 | D41: =C41-B41 -> 1800 | E41: =IF(B41=0,"无基期",D41/B41) -> 0.46985121 | F41: =D41/月度趋势!$D$14 -> 0.0062643122
A42: SAFETY | B42: 8297 | C42: 10069 | D42: =C42-B42 -> 1772 | E42: =IF(B42=0,"无基期",D42/B42) -> 0.21357117 | F42: =D42/月度趋势!$D$14 -> 0.0061668674
A43: Obstruction | B43: 13496 | C43: 15252 | D43: =C43-B43 -> 1756 | E43: =IF(B43=0,"无基期",D43/B43) -> 0.13011263 | F43: =D43/月度趋势!$D$14 -> 0.0061111846
A44: Bike/Roller/Skate | B44: 0 | C44: 1447 | D44: =C44-B44 -> 1447 | E44: =IF(B44=0,"无基期",D44/B44) -> 无基期 | F44: =D44/月度趋势!$D$14 -> 0.005035811
A45: Food Establishment | B45: 8618 | C45: 9757 | D45: =C45-B45 -> 1139 | E45: =IF(B45=0,"无基期",D45/B45) -> 0.13216524 | F45: =D45/月度趋势!$D$14 -> 0.0039639176
...

Sheet 峰值核查
A2: 雪冰尖峰与道路持续增长
A4: 同窗记录数；“剔除最高5天”仅削减2026年，用作保守压力测试，不是等长窗口同比。
A5: 类别 | B5: 2025年记录 | C5: 2026年记录 | D5: 2026最高5天 | E5: 最高5天占比 | F5: 剔除后2026 | G5: 相对2025增幅 | H5: 同比上升月数
A6: Snow or Ice | B6: 7990 | C6: 55230 | D6: 32819 | E6: =D6/C6 -> 0.59422415 | F6: =C6-D6 -> 22411 | G6: =F6/B6-1 -> 1.8048811 | H6: 3
A7: Street Condition | B7: 51211 | C7: 98920 | D7: 6243 | E7: =D7/C7 -> 0.063111605 | F7: =C7-D7 -> 92677 | G7: =F7/B7-1 -> 0.80970885 | H7: 7
A8: HEAT/HOT WATER | B8: 168645 | C8: 210519 | D8: 27221 | E8: =D8/C8 -> 0.12930424 | F8: =C8-D8 -> 183298 | G8: =F8/B8-1 -> 0.086886655 | H8: 8
A11: 描述层核查：坑洞增加 35,310 条，占道路状况净增量的 74.0%。
A13: 类别 | B13: 原始描述 | C13: 2025年记录 | D13: 2026年记录 | E13: 增加记录
A14: Street Condition | B14: Pothole | C14: 28918 | D14: 64228 | E14: =D14-C14 -> 35310
A15: HEAT/HOT WATER | B15: ENTIRE BUILDING | C15: 109037 | D15: 136399 | E15: =D15-C15 -> 27362
A16: Snow or Ice | B16: Sidewalk | C16: 6614 | D16: 26944 | E16: =D16-C16 -> 20330
A17: HEAT/HOT WATER | B17: APARTMENT ONLY | C17: 59608 | D17: 74120 | E17: =D17-C17 -> 14512
A18: Snow or Ice | B18: Snow Tracking | C18: 267 | D18: 14579 | E18: =D18-C18 -> 14312
A19: Snow or Ice | B19: Roadway | C19: 1102 | D19: 11457 | E19: =D19-C19 -> 10355
A20: Street Condition | B20: Cave-in | C20: 7088 | D20: 15327 | E20: =D20-C20 -> 8239
A21: Snow or Ice | B21: Pedestrian Feature | C21: 5 | D21: 2095 | E21: =D21-C21 -> 2090
A22: Street Condition | B22: Rough, Pitted or Cracked Roads | C22: 2227 | D22: 3338 | E22: =D22-C22 -> 1111
A23: Street Condition | B23: Defective Hardware | C23: 3773 | D23: 4848 | E23: =D23-C23 -> 1075
A24: Street Condition | B24: Failed Street Repair | C24: 2377 | D24: 3403 | E24: =D24-C24 -> 1026
A25: Street Condition | B25: Line/Marking - Faded | C25: 251 | D25: 660 | E25: =D25-C25 -> 409
A28: 雪冰集中度不能证明天气原因；缺少天气、人员和独立事件编号。
A29: 排除 Snow Tracking 描述后：雪冰仍从 7,723 增至 40,651 条（+426.4%）。
A32: 2026雪冰最高5天 | B32: 雪冰记录数
A33: 46077 | B33: 11370
A34: 46076 | B34: 6524
A35: 46049 | B35: 6048
A36: 46048 | B36: 4805
A37: 46050 | B37: 4072
A40: 最大单日 2026-02-24：11,370 条；涉及 9,355 个非空原始地址值。
A41: 地址数仅检验集中性，同址可能多次请求；地址文本未标准化，不等于独立事件。
A44: 日历月日 | B44: 2025雪冰 | C44: 2026雪冰
A45: 01-01 | B45: 0 | C45: 28
A46: 01-02 | B46: 2 | C46: 29
A47: 01-03 | B47: 5 | C47: 16
A48: 01-04 | B48: 10 | C48: 14
A49: 01-05 | B49: 12 | C49: 15
A50: 01-06 | B50: 156 | C50: 2
A51: 01-07 | B51: 362 | C51: 2
A52: 01-08 | B52: 51 | C52: 0
A53: 01-09 | B53: 36 | C53: 0
...

Sheet 渠道变化
A2: ONLINE 占比的变化能否由构成解释？
A4: ONLINE 保留源系统标签；不假定等于所有数字渠道，也不据此识别用户迁移。
A5: 原始渠道 | B5: 2025年记录 | C5: 2026年记录 | D5: 增加记录 | E5: 2025占比 | F5: 2026占比 | G5: 占比变化(pp)
A6: ONLINE | B6: 1011704 | C6: 1284422 | D6: =C6-B6 -> 272718 | E6: =B6/月度趋势!$B$14 -> 0.42531159 | F6: =C6/月度趋势!$C$14 -> 0.4817646 | G6: =(F6-E6)*100 -> 5.6453005
A7: UNKNOWN | B7: 178188 | C7: 244131 | D7: =C7-B7 -> 65943 | E7: =B7/月度趋势!$B$14 -> 0.074908691 | F7: =C7/月度趋势!$C$14 -> 0.091569339 | G7: =(F7-E7)*100 -> 1.6660648
A8: OTHER | B8: 12 | C8: 1912 | D8: =C8-B8 -> 1900 | E8: =B8/月度趋势!$B$14 -> 5.044696e-06 | F8: =C8/月度趋势!$C$14 -> 0.00071715831 | G8: =(F8-E8)*100 -> 0.071211362
A9: MOBILE | B9: 536111 | C9: 524772 | D9: =C9-B9 -> -11339 | E9: =B9/月度趋势!$B$14 -> 0.22537642 | F9: =C9/月度趋势!$C$14 -> 0.19683295 | G9: =(F9-E9)*100 -> -2.8543468
A10: PHONE | B10: 652721 | C10: 610841 | D10: =C10-B10 -> -41880 | E10: =B10/月度趋势!$B$14 -> 0.27439825 | F10: =C10/月度趋势!$C$14 -> 0.22911595 | G10: =(F10-E10)*100 -> -4.5282299
A13: 固定构成检查：共同存在的“月份 × 类别 × 机构”单元，固定2025年记录权重。
A15: 指标 | B15: 数值 | C15: 解释
A16: 共同单元2025记录 | B16: =SUM(D30:D1350) -> 2366687 | C16: 作为标准化权重分母
A17: 共同单元2026记录 | B17: =SUM(E30:E1350) -> 2651235 | C17: 2026年在相同单元内的记录
A18: 2025覆盖率 | B18: =B16/月度趋势!B14 -> 0.9949347 | C18: 共同单元记录 / 全部2025同窗记录
A19: 2026覆盖率 | B19: =B17/月度趋势!C14 -> 0.99443265 | C19: 共同单元记录 / 全部2026同窗记录
A20: 2025 ONLINE占比 | B20: =SUM(K30:K1350) -> 0.42559198 | C20: 共同单元，按2025年构成
A21: 固定构成2026 ONLINE占比 | B21: =SUM(L30:L1350) -> 0.49300654 | C21: 使用同一2025年构成权重
A22: 固定构成占比变化(pp) | B22: =(B21-B20)*100 -> 6.7414565 | C22: 同单元内的渠道结构仍有变化
A25: 结果支持渠道记录结构改变；无法确认是用户选择、接入方式或编码规则变化。
A26: 共同单元以外记录不参与标准化，覆盖率在上表披露；不把标准化比例当作实际比例。
A29: 月份 | B29: 原始类别 | C29: 机构 | D29: 2025总数 | E29: 2026总数 | F29: 2025 ONLINE | G29: 2026 ONLINE | H29: 2025权重 | I29: 2025占比 | J29: 2026占比 | K29: 基期加权项 | L29: 当期加权项
A30: 1 | B30: AHV Inspection Unit | C30: DOB | D30: 3 | E30: 3 | F30: 0 | G30: 0 | H30: =D30/$B$16 -> 1.2675947e-06 | I30: =F30/D30 -> 0 | J30: =G30/E30 -> 0 | K30: =H30*I30 -> 0 | L30: =H30*J30 -> 0
A31: 1 | B31: APPLIANCE | C31: HPD | D31: 2129 | E31: 2327 | F31: 831 | G31: 1021 | H31: =D31/$B$16 -> 0.00089956974 | I31: =F31/D31 -> 0.3903241 | J31: =G31/E31 -> 0.43876235 | K31: =H31*I31 -> 0.00035112374 | L31: =H31*J31 -> 0.00039469734
A32: 1 | B32: Abandoned Bike | C32: DSNY | D32: 172 | E32: 96 | F32: 117 | G32: 67 | H32: =D32/$B$16 -> 7.2675432e-05 | I32: =F32/D32 -> 0.68023256 | J32: =G32/E32 -> 0.69791667 | K32: =H32*I32 -> 4.9436195e-05 | L32: =H32*J32 -> 5.0721395e-05
A33: 1 | B33: Abandoned Vehicle | C33: NYPD | D33: 5626 | E33: 4549 | F33: 2494 | G33: 2495 | H33: =D33/$B$16 -> 0.0023771627 | I33: =F33/D33 -> 0.44329897 | J33: =G33/E33 -> 0.54847219 | K33: =H33*I33 -> 0.0010537938 | L33: =H33*J33 -> 0.0013038076
A34: 1 | B34: Air Quality | C34: DEP | D34: 817 | E34: 741 | F34: 611 | G34: 590 | H34: =D34/$B$16 -> 0.0003452083 | I34: =F34/D34 -> 0.74785802 | J34: =G34/E34 -> 0.79622132 | K34: =H34*I34 -> 0.0002581668 | L34: =H34*J34 -> 0.00027486221
A35: 1 | B35: Animal Facility - No Permit | C35: DOHMH | D35: 9 | E35: 2 | F35: 8 | G35: 1 | H35: =D35/$B$16 -> 3.8027842e-06 | I35: =F35/D35 -> 0.88888889 | J35: =G35/E35 -> 0.5 | K35: =H35*I35 -> 3.3802526e-06 | L35: =H35*J35 -> 1.9013921e-06
A36: 1 | B36: Animal in a Park | C36: DPR | D36: 291 | E36: 296 | F36: 156 | G36: 180 | H36: =D36/$B$16 -> 0.00012295669 | I36: =F36/D36 -> 0.53608247 | J36: =G36/E36 -> 0.60810811 | K36: =H36*I36 -> 6.5914927e-05 | L36: =H36*J36 -> 7.477096e-05
A37: 1 | B37: Animal-Abuse | C37: NYPD | D37: 841 | E37: 921 | F37: 550 | G37: 610 | H37: =D37/$B$16 -> 0.00035534906 | I37: =F37/D37 -> 0.65398335 | J37: =G37/E37 -> 0.66232356 | K37: =H37*I37 -> 0.00023239237 | L37: =H37*J37 -> 0.00023535605
A38: 1 | B38: Asbestos | C38: DEP | D38: 57 | E38: 73 | F38: 26 | G38: 28 | H38: =D38/$B$16 -> 2.40843e-05 | I38: =F38/D38 -> 0.45614035 | J38: =G38/E38 -> 0.38356164 | K38: =H38*I38 -> 1.0985821e-05 | L38: =H38*J38 -> 9.2378137e-06
A39: 1 | B39: Asbestos | C39: DOHMH | D39: 55 | E39: 43 | F39: 24 | G39: 21 | H39: =D39/$B$16 -> 2.3239237e-05 | I39: =F39/D39 -> 0.43636364 | J39: =G39/E39 -> 0.48837209 | K39: =H39*I39 -> 1.0140758e-05 | L39: =H39*J39 -> 1.1349395e-05
A40: 1 | B40: BEST/Site Safety | C40: DOB | D40: 33 | E40: 34 | F40: 0 | G40: 0 | H40: =D40/$B$16 -> 1.3943542e-05 | I40: =F40/D40 -> 0 | J40: =G40/E40 -> 0 | K40: =H40*I40 -> 0 | L40: =H40*J40 -> 0
A41: 1 | B41: Beach/Pool/Sauna Complaint | C41: DOHMH | D41: 9 | E41: 9 | F41: 7 | G41: 5 | H41: =D41/$B$16 -> 3.8027842e-06 | I41: =F41/D41 -> 0.77777778 | J41: =G41/E41 -> 0.55555556 | K41: =H41*I41 -> 2.9577211e-06 | L41: =H41*J41 -> 2.1126579e-06
... A1350: 8 | B1350: Wood Pile Remaining | C1350: DPR | D1350: 85 | E1350: 223 | F1350: 27 | G1350: 85 | H1350: =D1350/$B$16 -> 3.5915184e-05 | I1350: =F1350/D1350 -> 0.31764706 | J1350: =G1350/E1350 -> 0.38116592 | K1350: =H1350*I1350 -> 1.1408353e-05 | L1350: =H1350*J1350 -> 1.3689644e-05

Sheet 数据质量
A2: 数据边界与影响结论的质量问题
A4: 全量 7,525,498 条；缺失包括 NULL 和去除首尾空白后的空字符串，保留原始值。
A5: 检查项 | B5: 记录数/数量 | C5: 占全量比例 | D5: 对本项目的处理
A6: 全量请求记录 | B6: 7525498 | C6: =B6/$B$6 -> 1 | D6: 全量分母；无原始行删除
A7: 唯一键数量 | B7: 7525498 | C7: =B7/$B$6 -> 1 | D7: 等于行数，未做去重
A8: 缺失唯一键 | B8: 0 | C8: =B8/$B$6 -> 0 | D8: 无需补值
A9: 创建日期解析失败 | B9: 0 | C9: =B9/$B$6 -> 0 | D9: 创建时间可用于同窗筛选
A10: 关闭日期解析失败（非空） | B10: 0 | C10: =B10/$B$6 -> 0 | D10: 解析成功不代表业务有效
A11: 关闭日期缺失 | B11: 240304 | C11: =B11/$B$6 -> 0.031931973 | D11: 不会影响创建请求量；不以已关闭样本替代全部请求
A12: 关闭早于创建 | B12: 1877 | C12: =B12/$B$6 -> 0.00024941871 | D12: 不进入有效关闭时长统计；请求量保留
A13: 关闭等于创建 | B13: 135189 | C13: =B13/$B$6 -> 0.017964127 | D13: 未默认删除；可能含占位或行政动作，不能直接视为即时解决
A14: Closed 但无关闭日期 | B14: 15543 | C14: =B14/$B$6 -> 0.0020653783 | D14: 状态与日期不等价，不做机构效率排名
A15: 非Closed 但有关闭日期 | B15: 25388 | C15: =B15/$B$6 -> 0.0033735973 | D15: 部分来自DOB；不能只凭关闭日期断言已完成
A16: 关闭晚于2026-09-07 | B16: 1 | C16: =B16/$B$6 -> 1.3288157e-07 | D16: 记录67996481为2026-12-14；快照日期未提供，单独标记
A17: 行政区 Unspecified | B17: 6331 | C17: =B17/$B$6 -> 0.00084127323 | D17: 无人口分母，行政区记录量不代表人均问题率
A18: 渠道 UNKNOWN | B18: 590822 | C18: =B18/$B$6 -> 0.078509356 | D18: 保留为渠道类别，不填入ONLINE或PHONE
A21: 类别边界风险：DEP 的 Water System 在2026年8月降为0，同时维护类标签增多。
A22: 这与分类切换相容，但缺少映射文档，不能把 Water Maintenance 的倍增直接解读为需求爆发。
A23: 近月关闭观察期更短；本项目不发布平均结案时长排名或“处理效率提升”的结论。
A26: 原始字段 | B26: 缺失数量 | C26: 缺失比例 | D26: 本项目中的含义 / 用途
A27: unique_key | B27: 0 | C27: =B27/$B$6 -> 0 | D27: 请求标识；实测全量唯一，不代表独立现实事件
A28: created_date | B28: 0 | C28: =B28/$B$6 -> 0 | D28: 创建时间；按源值解析，不自行换时区
A29: closed_date | B29: 240304 | C29: =B29/$B$6 -> 0.031931973 | D29: 关闭日期；与状态不完全一致
A30: agency | B30: 0 | C30: =B30/$B$6 -> 0 | D30: 受理机构代码；不是人员或工时
A31: agency_name | B31: 0 | C31: =B31/$B$6 -> 0 | D31: 机构名称；描述性属性
A32: complaint_type | B32: 0 | C32: =B32/$B$6 -> 0 | D32: 原始请求类别；不擅自合并或重命名
A33: descriptor | B33: 21828 | C33: =B33/$B$6 -> 0.0029005389 | D33: 类别下的问题描述；用于钻取坑洞、雪冰等
A34: location_type | B34: 925173 | C34: =B34/$B$6 -> 0.12293844 | D34: 未纳入核心计算；缺失不统一补0或删行
A35: incident_zip | B35: 65559 | C35: =B35/$B$6 -> 0.0087115829 | D35: 邮编标识；保留字符串
A36: incident_address | B36: 270483 | C36: =B36/$B$6 -> 0.035942206 | D36: 地址文本；未标准化，仅检验集中性
A37: street_name | B37: 270674 | C37: =B37/$B$6 -> 0.035967586 | D37: 未纳入核心计算；缺失不统一补0或删行
A38: cross_street_1 | B38: 2174860 | C38: =B38/$B$6 -> 0.28899881 | D38: 未纳入核心计算；缺失不统一补0或删行
... A70: location | B70: 129696 | C70: =B70/$B$6 -> 0.017234208 | D70: 未纳入核心计算；缺失不统一补0或删行

Sheet 口径与复现
A2: 口径、字段解释与复现入口
A5: 项目 | B5: 定义与说明
A6: 数据来源 | B6: D:\项目1\原始数据 中25个Parquet；配套 D:\项目2\input\data_manifest.json。只读原件，未复制原始数据。
A7: 清单一致性 | B7: 25个文件的字节数、SHA-256、行数与结构已核对；44个字符串字段，各分片结构一致，日期均处于文件名界限内。
A8: 实测时间范围 | B8: 2024-09-07 00:00:00 至 2026-09-05 01:50:33；2024年9月及2026年9月不完整。日历日齐全仅证明有记录，不证明外部系统没有漏采。
A9: 记录粒度 | B9: 一行一条 unique_key 请求记录。键唯一不证明请求对应不同事件、不同人员或不同地址，重复投诉仍可能存在。
A10: 比较窗口 | B10: 2025-01-01 ≤ created < 2025-09-01，对比2026年相同月日，两窗各243天；不限制状态、类别、机构、行政区或渠道。
A11: 字段语义边界 | B11: 未提供数据字典、分类变更说明或采集快照时点。字段解释依名称及实际值作最低限度操作定义，不当作经外部核实的业务规则。
A12: 计数和比率 | B12: 记录数为COUNT(*)，核实unique_key全量唯一；增幅=(当期−基期)/基期，贡献率=分组净增/全部净增，零基期显示“无基期”。
A13: 预处理 | B13: 日期用TRY_CAST解析；空值审计包含空白。类别与渠道保留原始标签，不更改大小写、不合并近似标签，不删除异常时长行。
A14: 标准化方法 | B14: 仅共同存在的月份×类别×机构单元；每单元2025总数/共同单元2025总数为权重，分别加权两年ONLINE占比。明细及Excel公式见渠道变化。
A15: 尖峰测试 | B15: 2026各类别自身最高5个自然日从当期剔除，基期保持完整，属于刻意更苛刻的单侧敏感性检查，不作等长同比指标。
A16: 事实与解释 | B16: 增长、描述结构与渠道占比是数据内事实。天气、报送规则、真实问题数量和个体迁移均未被识别；仅可提出后续验证方向。
... A23: 原始记录回查 | B23: evidence/peak_records.csv 与 anomaly_records.csv 保留请求键，可在原始Parquet定位；不输出完整地址明细。
