Workbook

Sheet 评测总览
B1: AI 评测总览 · 现行 S | R1: 查看单个 AI ›
B2: NYC311 自主交付评测 · 模型、宿主与当轮条件共同构成比较单位
B3: 轮次 | C3: 第二轮 | E3: ▼ | F3: 六系统配对；Claude第一轮单列，Kimi未评分
B4: 配对系统数 | E4: 第一轮平均 S | H4: 第二轮平均 S | K4: 最短耗时（分钟）
B5: =COUNT(C9:C14) -> 6 | E5: =AVERAGE(C9:C14) -> 71.666667 | H5: =AVERAGE(D9:D14) -> 81.125 | K5: =MIN(E9:E13) -> 9.5915833
B8: AI | C8: 首轮 S | D8: 次轮 S | E8: 分钟 | F8: API目录价（元） | H8: AWR | I8: 修正 | J8: 总 Token | L8: 运行工具 | N8: 状态
B9: GPT | C9: =IF(COUNTIFS(评分与用量!$A$2:$A$634,B9,评分与用量!$B$2:$B$634,"第一轮",评分与用量!$C$2:$C$634,"S分项")=0,"",SUMIFS(评分与用量!$E$2:$E$634,评分与用量!$A$2:$A$634,B9,评分与用量!$B$2:$B$634,"第一轮",评分与用量!$C$2:$C$634,"S分项")) -> 88 | D9: =IF(COUNTIFS(评分与用量!$A$2:$A$634,B9,评分与用量!$B$2:$B$634,"第二轮",评分与用量!$C$2:$C$634,"S分项")=0,"",SUMIFS(评分与用量!$E$2:$E$634,评分与用量!$A$2:$A$634,B9,评分与用量!$B$2:$B$634,"第二轮",评分与用量!$C$2:$C$634,"S分项")) -> 98.5 | E9: =IF(SUMPRODUCT((运行记录!$A$2:$A$16=$B9)*(运行记录!$B$2:$B$16=$C$3)*ISNUMBER(运行记录!$M$2:$M$16))=0,"",SUMIFS(运行记录!$M$2:$M$16,运行记录!$A$2:$A$16,$B9,运行记录!$B$2:$B$16,$C$3)) -> 17.7814 | F9: =IF(OR(BC9="",BD9=""),"—",IF(ABS(BC9-BD9)<0.005,TEXT(BC9,"0.00"),TEXT(BC9,"0.00")&"–"&TEXT(BD9,"0.00"))) -> 38.96 | H9: =IF(COUNTIFS(行为记录!$A$2:$A$816,$B9,行为记录!$B$2:$B$816,$C$3,行为记录!$L$2:$L$816,"<>管理动作")=0,"",COUNTIFS(行为记录!$A$2:$A$816,$B9,行为记录!$B$2:$B$816,$C$3,行为记录!$L$2:$L$816,"确认无收益")/(COUNTIFS(行为记录!$A$2:$A$816,$B9,行为记录!$B$2:$B$816,$C$3,行为记录!$L$2:$L$816,"直接贡献交付")+COUNTIFS(行为记录!$A$2:$A$816,$B9,行为记录!$B$2:$B$816,$C$3,行为记录!$L$2:$L$816,"必要探索")+COUNTIFS(行为记录!$A$2:$A$816,$B9,行为记录!$B$2:$B$816,$C$3,行为记录!$L$2:$L$816,"确认无收益"))) -> 0.0625 | I9: =IF(COUNTIFS(评分与用量!$A$2:$A$623,$B9,评分与用量!$B$2:$B$623,$C$3,评分与用量!$C$2:$C$623,"人工负担证据",评分与用量!$D$2:$D$623,"首交后需处理任务数")=0,"",SUMIFS(评分与用量!$E$2:$E$623,评分与用量!$A$2:$A$623,$B9,评分与用量!$B$2:$B$623,$C$3,评分与用量!$C$2:$C$623,"人工负担证据",评分与用量!$D$2:$D$623,"首交后需处理任务数")) -> 0 | J9: =IF(SUMPRODUCT((运行记录!$A$2:$A$16=$B9)*(运行记录!$B$2:$B$16=$C$3)*ISNUMBER(运行记录!$P$2:$P$16))=0,"",SUMIFS(运行记录!$P$2:$P$16,运行记录!$A$2:$A$16,$B9,运行记录!$B$2:$B$16,$C$3)) -> 3244918 | L9: =IF(COUNTIFS(运行记录!$A$2:$A$16,$B9,运行记录!$B$2:$B$16,$C$3)=0,"未运行",INDEX(运行记录!$E$2:$E$16,SUMPRODUCT((运行记录!$A$2:$A$16=$B9)*(运行记录!$B$2:$B$16=$C$3)*(ROW(运行记录!$A$2:$A$16)-1)))) -> Codex | N9: =IF(COUNTIFS(运行记录!$A$2:$A$16,$B9,运行记录!$B$2:$B$16,$C$3)=0,"未运行",INDEX(运行记录!$C$2:$C$16,SUMPRODUCT((运行记录!$A$2:$A$16=$B9)*(运行记录!$B$2:$B$16=$C$3)*(ROW(运行记录!$A$2:$A$16)-1)))) -> 已完成 | BC9: =IF(SUMPRODUCT((运行记录!$A$2:$A$16=$B9)*(运行记录!$B$2:$B$16=$C$3)*ISNUMBER(运行记录!$Q$2:$Q$16))=0,"",SUMIFS(运行记录!$Q$2:$Q$16,运行记录!$A$2:$A$16,$B9,运行记录!$B$2:$B$16,$C$3)) -> 38.958408 | BD9: =IF(SUMPRODUCT((运行记录!$A$2:$A$16=$B9)*(运行记录!$B$2:$B$16=$C$3)*ISNUMBER(运行记录!$R$2:$R$16))=0,"",SUMIFS(运行记录!$R$2:$R$16,运行记录!$A$2:$A$16,$B9,运行记录!$B$2:$B$16,$C$3)) -> 38.958408 | BE9: =C9 -> 88 | BF9: =D9 -> 98.5
B10: Grok | C10: =IF(COUNTIFS(评分与用量!$A$2:$A$634,B10,评分与用量!$B$2:$B$634,"第一轮",评分与用量!$C$2:$C$634,"S分项")=0,"",SUMIFS(评分与用量!$E$2:$E$634,评分与用量!$A$2:$A$634,B10,评分与用量!$B$2:$B$634,"第一轮",评分与用量!$C$2:$C$634,"S分项")) -> 84.5 | D10: =IF(COUNTIFS(评分与用量!$A$2:$A$634,B10,评分与用量!$B$2:$B$634,"第二轮",评分与用量!$C$2:$C$634,"S分项")=0,"",SUMIFS(评分与用量!$E$2:$E$634,评分与用量!$A$2:$A$634,B10,评分与用量!$B$2:$B$634,"第二轮",评分与用量!$C$2:$C$634,"S分项")) -> 85.25 | E10: =IF(SUMPRODUCT((运行记录!$A$2:$A$16=$B10)*(运行记录!$B$2:$B$16=$C$3)*ISNUMBER(运行记录!$M$2:$M$16))=0,"",SUMIFS(运行记录!$M$2:$M$16,运行记录!$A$2:$A$16,$B10,运行记录!$B$2:$B$16,$C$3)) -> 11.707417 | F10: =IF(OR(BC10="",BD10=""),"—",IF(ABS(BC10-BD10)<0.005,TEXT(BC10,"0.00"),TEXT(BC10,"0.00")&"–"&TEXT(BD10,"0.00"))) -> 9.86 | H10: =IF(COUNTIFS(行为记录!$A$2:$A$816,$B10,行为记录!$B$2:$B$816,$C$3,行为记录!$L$2:$L$816,"<>管理动作")=0,"",COUNTIFS(行为记录!$A$2:$A$816,$B10,行为记录!$B$2:$B$816,$C$3,行为记录!$L$2:$L$816,"确认无收益")/(COUNTIFS(行为记录!$A$2:$A$816,$B10,行为记录!$B$2:$B$816,$C$3,行为记录!$L$2:$L$816,"直接贡献交付")+COUNTIFS(行为记录!$A$2:$A$816,$B10,行为记录!$B$2:$B$816,$C$3,行为记录!$L$2:$L$816,"必要探索")+COUNTIFS(行为记录!$A$2:$A$816,$B10,行为记录!$B$2:$B$816,$C$3,行为记录!$L$2:$L$816,"确认无收益"))) -> 0 | I10: =IF(COUNTIFS(评分与用量!$A$2:$A$623,$B10,评分与用量!$B$2:$B$623,$C$3,评分与用量!$C$2:$C$623,"人工负担证据",评分与用量!$D$2:$D$623,"首交后需处理任务数")=0,"",SUMIFS(评分与用量!$E$2:$E$623,评分与用量!$A$2:$A$623,$B10,评分与用量!$B$2:$B$623,$C$3,评分与用量!$C$2:$C$623,"人工负担证据",评分与用量!$D$2:$D$623,"首交后需处理任务数")) -> 1 | J10: =IF(SUMPRODUCT((运行记录!$A$2:$A$16=$B10)*(运行记录!$B$2:$B$16=$C$3)*ISNUMBER(运行记录!$P$2:$P$16))=0,"",SUMIFS(运行记录!$P$2:$P$16,运行记录!$A$2:$A$16,$B10,运行记录!$B$2:$B$16,$C$3)) -> 1597244 | L10: =IF(COUNTIFS(运行记录!$A$2:$A$16,$B10,运行记录!$B$2:$B$16,$C$3)=0,"未运行",INDEX(运行记录!$E$2:$E$16,SUMPRODUCT((运行记录!$A$2:$A$16=$B10)*(运行记录!$B$2:$B$16=$C$3)*(ROW(运行记录!$A$2:$A$16)-1)))) -> Cursor | N10: =IF(COUNTIFS(运行记录!$A$2:$A$16,$B10,运行记录!$B$2:$B$16,$C$3)=0,"未运行",INDEX(运行记录!$C$2:$C$16,SUMPRODUCT((运行记录!$A$2:$A$16=$B10)*(运行记录!$B$2:$B$16=$C$3)*(ROW(运行记录!$A$2:$A$16)-1)))) -> 已完成 | BC10: =IF(SUMPRODUCT((运行记录!$A$2:$A$16=$B10)*(运行记录!$B$2:$B$16=$C$3)*ISNUMBER(运行记录!$Q$2:$Q$16))=0,"",SUMIFS(运行记录!$Q$2:$Q$16,运行记录!$A$2:$A$16,$B10,运行记录!$B$2:$B$16,$C$3)) -> 9.8583229 | BD10: =IF(SUMPRODUCT((运行记录!$A$2:$A$16=$B10)*(运行记录!$B$2:$B$16=$C$3)*ISNUMBER(运行记录!$R$2:$R$16))=0,"",SUMIFS(运行记录!$R$2:$R$16,运行记录!$A$2:$A$16,$B10,运行记录!$B$2:$B$16,$C$3)) -> 9.8583229 | BE10: =C10 -> 84.5 | BF10: =D10 -> 85.25
B11: DeepSeek | C11: =IF(COUNTIFS(评分与用量!$A$2:$A$634,B11,评分与用量!$B$2:$B$634,"第一轮",评分与用量!$C$2:$C$634,"S分项")=0,"",SUMIFS(评分与用量!$E$2:$E$634,评分与用量!$A$2:$A$634,B11,评分与用量!$B$2:$B$634,"第一轮",评分与用量!$C$2:$C$634,"S分项")) -> 76.5 | D11: =IF(COUNTIFS(评分与用量!$A$2:$A$634,B11,评分与用量!$B$2:$B$634,"第二轮",评分与用量!$C$2:$C$634,"S分项")=0,"",SUMIFS(评分与用量!$E$2:$E$634,评分与用量!$A$2:$A$634,B11,评分与用量!$B$2:$B$634,"第二轮",评分与用量!$C$2:$C$634,"S分项")) -> 87.25 | E11: =IF(SUMPRODUCT((运行记录!$A$2:$A$16=$B11)*(运行记录!$B$2:$B$16=$C$3)*ISNUMBER(运行记录!$M$2:$M$16))=0,"",SUMIFS(运行记录!$M$2:$M$16,运行记录!$A$2:$A$16,$B11,运行记录!$B$2:$B$16,$C$3)) -> 21.701233 | F11: =IF(OR(BC11="",BD11=""),"—",IF(ABS(BC11-BD11)<0.005,TEXT(BC11,"0.00"),TEXT(BC11,"0.00")&"–"&TEXT(BD11,"0.00"))) -> 1.37–2.74 | H11: =IF(COUNTIFS(行为记录!$A$2:$A$816,$B11,行为记录!$B$2:$B$816,$C$3,行为记录!$L$2:$L$816,"<>管理动作")=0,"",COUNTIFS(行为记录!$A$2:$A$816,$B11,行为记录!$B$2:$B$816,$C$3,行为记录!$L$2:$L$816,"确认无收益")/(COUNTIFS(行为记录!$A$2:$A$816,$B11,行为记录!$B$2:$B$816,$C$3,行为记录!$L$2:$L$816,"直接贡献交付")+COUNTIFS(行为记录!$A$2:$A$816,$B11,行为记录!$B$2:$B$816,$C$3,行为记录!$L$2:$L$816,"必要探索")+COUNTIFS(行为记录!$A$2:$A$816,$B11,行为记录!$B$2:$B$816,$C$3,行为记录!$L$2:$L$816,"确认无收益"))) -> 0.011363636 | I11: =IF(COUNTIFS(评分与用量!$A$2:$A$623,$B11,评分与用量!$B$2:$B$623,$C$3,评分与用量!$C$2:$C$623,"人工负担证据",评分与用量!$D$2:$D$623,"首交后需处理任务数")=0,"",SUMIFS(评分与用量!$E$2:$E$623,评分与用量!$A$2:$A$623,$B11,评分与用量!$B$2:$B$623,$C$3,评分与用量!$C$2:$C$623,"人工负担证据",评分与用量!$D$2:$D$623,"首交后需处理任务数")) -> 1 | J11: =IF(SUMPRODUCT((运行记录!$A$2:$A$16=$B11)*(运行记录!$B$2:$B$16=$C$3)*ISNUMBER(运行记录!$P$2:$P$16))=0,"",SUMIFS(运行记录!$P$2:$P$16,运行记录!$A$2:$A$16,$B11,运行记录!$B$2:$B$16,$C$3)) -> 8980596 | L11: =IF(COUNTIFS(运行记录!$A$2:$A$16,$B11,运行记录!$B$2:$B$16,$C$3)=0,"未运行",INDEX(运行记录!$E$2:$E$16,SUMPRODUCT((运行记录!$A$2:$A$16=$B11)*(运行记录!$B$2:$B$16=$C$3)*(ROW(运行记录!$A$2:$A$16)-1)))) -> Claude Code | N11: =IF(COUNTIFS(运行记录!$A$2:$A$16,$B11,运行记录!$B$2:$B$16,$C$3)=0,"未运行",INDEX(运行记录!$C$2:$C$16,SUMPRODUCT((运行记录!$A$2:$A$16=$B11)*(运行记录!$B$2:$B$16=$C$3)*(ROW(运行记录!$A$2:$A$16)-1)))) -> 已完成 | BC11: =IF(SUMPRODUCT((运行记录!$A$2:$A$16=$B11)*(运行记录!$B$2:$B$16=$C$3)*ISNUMBER(运行记录!$Q$2:$Q$16))=0,"",SUMIFS(运行记录!$Q$2:$Q$16,运行记录!$A$2:$A$16,$B11,运行记录!$B$2:$B$16,$C$3)) -> 1.3686114 | BD11: =IF(SUMPRODUCT((运行记录!$A$2:$A$16=$B11)*(运行记录!$B$2:$B$16=$C$3)*ISNUMBER(运行记录!$R$2:$R$16))=0,"",SUMIFS(运行记录!$R$2:$R$16,运行记录!$A$2:$A$16,$B11,运行记录!$B$2:$B$16,$C$3)) -> 2.7372228 | BE11: =C11 -> 76.5 | BF11: =D11 -> 87.25
B12: GLM | C12: =IF(COUNTIFS(评分与用量!$A$2:$A$634,B12,评分与用量!$B$2:$B$634,"第一轮",评分与用量!$C$2:$C$634,"S分项")=0,"",SUMIFS(评分与用量!$E$2:$E$634,评分与用量!$A$2:$A$634,B12,评分与用量!$B$2:$B$634,"第一轮",评分与用量!$C$2:$C$634,"S分项")) -> 74 | D12: =IF(COUNTIFS(评分与用量!$A$2:$A$634,B12,评分与用量!$B$2:$B$634,"第二轮",评分与用量!$C$2:$C$634,"S分项")=0,"",SUMIFS(评分与用量!$E$2:$E$634,评分与用量!$A$2:$A$634,B12,评分与用量!$B$2:$B$634,"第二轮",评分与用量!$C$2:$C$634,"S分项")) -> 81 | E12: =IF(SUMPRODUCT((运行记录!$A$2:$A$16=$B12)*(运行记录!$B$2:$B$16=$C$3)*ISNUMBER(运行记录!$M$2:$M$16))=0,"",SUMIFS(运行记录!$M$2:$M$16,运行记录!$A$2:$A$16,$B12,运行记录!$B$2:$B$16,$C$3)) -> 9.5915833 | F12: =IF(OR(BC12="",BD12=""),"—",IF(ABS(BC12-BD12)<0.005,TEXT(BC12,"0.00"),TEXT(BC12,"0.00")&"–"&TEXT(BD12,"0.00"))) -> 6.48 | H12: =IF(COUNTIFS(行为记录!$A$2:$A$816,$B12,行为记录!$B$2:$B$816,$C$3,行为记录!$L$2:$L$816,"<>管理动作")=0,"",COUNTIFS(行为记录!$A$2:$A$816,$B12,行为记录!$B$2:$B$816,$C$3,行为记录!$L$2:$L$816,"确认无收益")/(COUNTIFS(行为记录!$A$2:$A$816,$B12,行为记录!$B$2:$B$816,$C$3,行为记录!$L$2:$L$816,"直接贡献交付")+COUNTIFS(行为记录!$A$2:$A$816,$B12,行为记录!$B$2:$B$816,$C$3,行为记录!$L$2:$L$816,"必要探索")+COUNTIFS(行为记录!$A$2:$A$816,$B12,行为记录!$B$2:$B$816,$C$3,行为记录!$L$2:$L$816,"确认无收益"))) -> 0.048780488 | I12: =IF(COUNTIFS(评分与用量!$A$2:$A$623,$B12,评分与用量!$B$2:$B$623,$C$3,评分与用量!$C$2:$C$623,"人工负担证据",评分与用量!$D$2:$D$623,"首交后需处理任务数")=0,"",SUMIFS(评分与用量!$E$2:$E$623,评分与用量!$A$2:$A$623,$B12,评分与用量!$B$2:$B$623,$C$3,评分与用量!$C$2:$C$623,"人工负担证据",评分与用量!$D$2:$D$623,"首交后需处理任务数")) -> 1 | J12: =IF(SUMPRODUCT((运行记录!$A$2:$A$16=$B12)*(运行记录!$B$2:$B$16=$C$3)*ISNUMBER(运行记录!$P$2:$P$16))=0,"",SUMIFS(运行记录!$P$2:$P$16,运行记录!$A$2:$A$16,$B12,运行记录!$B$2:$B$16,$C$3)) -> 2456581 | L12: =IF(COUNTIFS(运行记录!$A$2:$A$16,$B12,运行记录!$B$2:$B$16,$C$3)=0,"未运行",INDEX(运行记录!$E$2:$E$16,SUMPRODUCT((运行记录!$A$2:$A$16=$B12)*(运行记录!$B$2:$B$16=$C$3)*(ROW(运行记录!$A$2:$A$16)-1)))) -> Claude Code | N12: =IF(COUNTIFS(运行记录!$A$2:$A$16,$B12,运行记录!$B$2:$B$16,$C$3)=0,"未运行",INDEX(运行记录!$C$2:$C$16,SUMPRODUCT((运行记录!$A$2:$A$16=$B12)*(运行记录!$B$2:$B$16=$C$3)*(ROW(运行记录!$A$2:$A$16)-1)))) -> 已完成 | BC12: =IF(SUMPRODUCT((运行记录!$A$2:$A$16=$B12)*(运行记录!$B$2:$B$16=$C$3)*ISNUMBER(运行记录!$Q$2:$Q$16))=0,"",SUMIFS(运行记录!$Q$2:$Q$16,运行记录!$A$2:$A$16,$B12,运行记录!$B$2:$B$16,$C$3)) -> 6.480276 | BD12: =IF(SUMPRODUCT((运行记录!$A$2:$A$16=$B12)*(运行记录!$B$2:$B$16=$C$3)*ISNUMBER(运行记录!$R$2:$R$16))=0,"",SUMIFS(运行记录!$R$2:$R$16,运行记录!$A$2:$A$16,$B12,运行记录!$B$2:$B$16,$C$3)) -> 6.480276 | BE12: =C12 -> 74 | BF12: =D12 -> 81
B13: Qwen | C13: =IF(COUNTIFS(评分与用量!$A$2:$A$634,B13,评分与用量!$B$2:$B$634,"第一轮",评分与用量!$C$2:$C$634,"S分项")=0,"",SUMIFS(评分与用量!$E$2:$E$634,评分与用量!$A$2:$A$634,B13,评分与用量!$B$2:$B$634,"第一轮",评分与用量!$C$2:$C$634,"S分项")) -> 67.5 | D13: =IF(COUNTIFS(评分与用量!$A$2:$A$634,B13,评分与用量!$B$2:$B$634,"第二轮",评分与用量!$C$2:$C$634,"S分项")=0,"",SUMIFS(评分与用量!$E$2:$E$634,评分与用量!$A$2:$A$634,B13,评分与用量!$B$2:$B$634,"第二轮",评分与用量!$C$2:$C$634,"S分项")) -> 75.25 | E13: =IF(SUMPRODUCT((运行记录!$A$2:$A$16=$B13)*(运行记录!$B$2:$B$16=$C$3)*ISNUMBER(运行记录!$M$2:$M$16))=0,"",SUMIFS(运行记录!$M$2:$M$16,运行记录!$A$2:$A$16,$B13,运行记录!$B$2:$B$16,$C$3)) -> 60.205983 | F13: =IF(OR(BC13="",BD13=""),"—",IF(ABS(BC13-BD13)<0.005,TEXT(BC13,"0.00"),TEXT(BC13,"0.00")&"–"&TEXT(BD13,"0.00"))) -> 14.33 | H13: =IF(COUNTIFS(行为记录!$A$2:$A$816,$B13,行为记录!$B$2:$B$816,$C$3,行为记录!$L$2:$L$816,"<>管理动作")=0,"",COUNTIFS(行为记录!$A$2:$A$816,$B13,行为记录!$B$2:$B$816,$C$3,行为记录!$L$2:$L$816,"确认无收益")/(COUNTIFS(行为记录!$A$2:$A$816,$B13,行为记录!$B$2:$B$816,$C$3,行为记录!$L$2:$L$816,"直接贡献交付")+COUNTIFS(行为记录!$A$2:$A$816,$B13,行为记录!$B$2:$B$816,$C$3,行为记录!$L$2:$L$816,"必要探索")+COUNTIFS(行为记录!$A$2:$A$816,$B13,行为记录!$B$2:$B$816,$C$3,行为记录!$L$2:$L$816,"确认无收益"))) -> 0 | I13: =IF(COUNTIFS(评分与用量!$A$2:$A$623,$B13,评分与用量!$B$2:$B$623,$C$3,评分与用量!$C$2:$C$623,"人工负担证据",评分与用量!$D$2:$D$623,"首交后需处理任务数")=0,"",SUMIFS(评分与用量!$E$2:$E$623,评分与用量!$A$2:$A$623,$B13,评分与用量!$B$2:$B$623,$C$3,评分与用量!$C$2:$C$623,"人工负担证据",评分与用量!$D$2:$D$623,"首交后需处理任务数")) -> 2 | J13: =IF(SUMPRODUCT((运行记录!$A$2:$A$16=$B13)*(运行记录!$B$2:$B$16=$C$3)*ISNUMBER(运行记录!$P$2:$P$16))=0,"",SUMIFS(运行记录!$P$2:$P$16,运行记录!$A$2:$A$16,$B13,运行记录!$B$2:$B$16,$C$3)) -> 8288450 | L13: =IF(COUNTIFS(运行记录!$A$2:$A$16,$B13,运行记录!$B$2:$B$16,$C$3)=0,"未运行",INDEX(运行记录!$E$2:$E$16,SUMPRODUCT((运行记录!$A$2:$A$16=$B13)*(运行记录!$B$2:$B$16=$C$3)*(ROW(运行记录!$A$2:$A$16)-1)))) -> Claude Code | N13: =IF(COUNTIFS(运行记录!$A$2:$A$16,$B13,运行记录!$B$2:$B$16,$C$3)=0,"未运行",INDEX(运行记录!$C$2:$C$16,SUMPRODUCT((运行记录!$A$2:$A$16=$B13)*(运行记录!$B$2:$B$16=$C$3)*(ROW(运行记录!$A$2:$A$16)-1)))) -> 已完成 | BC13: =IF(SUMPRODUCT((运行记录!$A$2:$A$16=$B13)*(运行记录!$B$2:$B$16=$C$3)*ISNUMBER(运行记录!$Q$2:$Q$16))=0,"",SUMIFS(运行记录!$Q$2:$Q$16,运行记录!$A$2:$A$16,$B13,运行记录!$B$2:$B$16,$C$3)) -> 14.328685 | BD13: =IF(SUMPRODUCT((运行记录!$A$2:$A$16=$B13)*(运行记录!$B$2:$B$16=$C$3)*ISNUMBER(运行记录!$R$2:$R$16))=0,"",SUMIFS(运行记录!$R$2:$R$16,运行记录!$A$2:$A$16,$B13,运行记录!$B$2:$B$16,$C$3)) -> 14.328685 | BE13: =C13 -> 67.5 | BF13: =D13 -> 75.25
B14: Gemini | C14: =IF(COUNTIFS(评分与用量!$A$2:$A$634,B14,评分与用量!$B$2:$B$634,"第一轮",评分与用量!$C$2:$C$634,"S分项")=0,"",SUMIFS(评分与用量!$E$2:$E$634,评分与用量!$A$2:$A$634,B14,评分与用量!$B$2:$B$634,"第一轮",评分与用量!$C$2:$C$634,"S分项")) -> 39.5 | D14: =IF(COUNTIFS(评分与用量!$A$2:$A$634,B14,评分与用量!$B$2:$B$634,"第二轮",评分与用量!$C$2:$C$634,"S分项")=0,"",SUMIFS(评分与用量!$E$2:$E$634,评分与用量!$A$2:$A$634,B14,评分与用量!$B$2:$B$634,"第二轮",评分与用量!$C$2:$C$634,"S分项")) -> 59.5 | E14: =IF(SUMPRODUCT((运行记录!$A$2:$A$16=$B14)*(运行记录!$B$2:$B$16=$C$3)*ISNUMBER(运行记录!$M$2:$M$16))=0,"",SUMIFS(运行记录!$M$2:$M$16,运行记录!$A$2:$A$16,$B14,运行记录!$B$2:$B$16,$C$3)) -> 6.0697351 | F14: =IF(OR(BC14="",BD14=""),"—",IF(ABS(BC14-BD14)<0.005,TEXT(BC14,"0.00"),TEXT(BC14,"0.00")&"–"&TEXT(BD14,"0.00"))) -> 5.12 | H14: =IF(COUNTIFS(行为记录!$A$2:$A$816,$B14,行为记录!$B$2:$B$816,$C$3,行为记录!$L$2:$L$816,"<>管理动作")=0,"",COUNTIFS(行为记录!$A$2:$A$816,$B14,行为记录!$B$2:$B$816,$C$3,行为记录!$L$2:$L$816,"确认无收益")/(COUNTIFS(行为记录!$A$2:$A$816,$B14,行为记录!$B$2:$B$816,$C$3,行为记录!$L$2:$L$816,"直接贡献交付")+COUNTIFS(行为记录!$A$2:$A$816,$B14,行为记录!$B$2:$B$816,$C$3,行为记录!$L$2:$L$816,"必要探索")+COUNTIFS(行为记录!$A$2:$A$816,$B14,行为记录!$B$2:$B$816,$C$3,行为记录!$L$2:$L$816,"确认无收益"))) -> 0 | I14: =IF(COUNTIFS(评分与用量!$A$2:$A$623,$B14,评分与用量!$B$2:$B$623,$C$3,评分与用量!$C$2:$C$623,"人工负担证据",评分与用量!$D$2:$D$623,"首交后需处理任务数")=0,"",SUMIFS(评分与用量!$E$2:$E$623,评分与用量!$A$2:$A$623,$B14,评分与用量!$B$2:$B$623,$C$3,评分与用量!$C$2:$C$623,"人工负担证据",评分与用量!$D$2:$D$623,"首交后需处理任务数")) -> 5 | J14: =IF(SUMPRODUCT((运行记录!$A$2:$A$16=$B14)*(运行记录!$B$2:$B$16=$C$3)*ISNUMBER(运行记录!$P$2:$P$16))=0,"",SUMIFS(运行记录!$P$2:$P$16,运行记录!$A$2:$A$16,$B14,运行记录!$B$2:$B$16,$C$3)) -> 2502140 | L14: =IF(COUNTIFS(运行记录!$A$2:$A$16,$B14,运行记录!$B$2:$B$16,$C$3)=0,"未运行",INDEX(运行记录!$E$2:$E$16,SUMPRODUCT((运行记录!$A$2:$A$16=$B14)*(运行记录!$B$2:$B$16=$C$3)*(ROW(运行记录!$A$2:$A$16)-1)))) -> Antigravity | N14: =IF(COUNTIFS(运行记录!$A$2:$A$16,B14,运行记录!$B$2:$B$16,$C$3)=0,"未运行",INDEX(运行记录!$C$2:$C$16,MATCH(1,INDEX((运行记录!$A$2:$A$16=B14)*(运行记录!$B$2:$B$16=$C$3),0),0))) -> 已完成 | BC14: =IF(SUMPRODUCT((运行记录!$A$2:$A$16=$B14)*(运行记录!$B$2:$B$16=$C$3)*ISNUMBER(运行记录!$Q$2:$Q$16))=0,"",SUMIFS(运行记录!$Q$2:$Q$16,运行记录!$A$2:$A$16,$B14,运行记录!$B$2:$B$16,$C$3)) -> 5.1199395 | BD14: =IF(SUMPRODUCT((运行记录!$A$2:$A$16=$B14)*(运行记录!$B$2:$B$16=$C$3)*ISNUMBER(运行记录!$R$2:$R$16))=0,"",SUMIFS(运行记录!$R$2:$R$16,运行记录!$A$2:$A$16,$B14,运行记录!$B$2:$B$16,$C$3)) -> 5.1199395 | BE14: =C14 -> 39.5 | BF14: =D14 -> 59.5
B15: Kimi | C15: =IF(COUNTIFS(评分与用量!$A$2:$A$634,B15,评分与用量!$B$2:$B$634,"第一轮",评分与用量!$C$2:$C$634,"S分项")=0,"",SUMIFS(评分与用量!$E$2:$E$634,评分与用量!$A$2:$A$634,B15,评分与用量!$B$2:$B$634,"第一轮",评分与用量!$C$2:$C$634,"S分项")) | D15: =IF(COUNTIFS(评分与用量!$A$2:$A$634,B15,评分与用量!$B$2:$B$634,"第二轮",评分与用量!$C$2:$C$634,"S分项")=0,"",SUMIFS(评分与用量!$E$2:$E$634,评分与用量!$A$2:$A$634,B15,评分与用量!$B$2:$B$634,"第二轮",评分与用量!$C$2:$C$634,"S分项")) | E15: =IF(SUMPRODUCT((运行记录!$A$2:$A$16=$B15)*(运行记录!$B$2:$B$16=$C$3)*ISNUMBER(运行记录!$M$2:$M$16))=0,"",SUMIFS(运行记录!$M$2:$M$16,运行记录!$A$2:$A$16,$B15,运行记录!$B$2:$B$16,$C$3)) -> 2.6456167 | F15: =IF(OR(BC15="",BD15=""),"—",IF(ABS(BC15-BD15)<0.005,TEXT(BC15,"0.00"),TEXT(BC15,"0.00")&"–"&TEXT(BD15,"0.00"))) -> 1.48 | H15: =IF(COUNTIFS(行为记录!$A$2:$A$816,$B15,行为记录!$B$2:$B$816,$C$3,行为记录!$L$2:$L$816,"<>管理动作")=0,"",COUNTIFS(行为记录!$A$2:$A$816,$B15,行为记录!$B$2:$B$816,$C$3,行为记录!$L$2:$L$816,"确认无收益")/(COUNTIFS(行为记录!$A$2:$A$816,$B15,行为记录!$B$2:$B$816,$C$3,行为记录!$L$2:$L$816,"直接贡献交付")+COUNTIFS(行为记录!$A$2:$A$816,$B15,行为记录!$B$2:$B$816,$C$3,行为记录!$L$2:$L$816,"必要探索")+COUNTIFS(行为记录!$A$2:$A$816,$B15,行为记录!$B$2:$B$816,$C$3,行为记录!$L$2:$L$816,"确认无收益"))) -> 0.92857143 | I15: =IF(COUNTIFS(评分与用量!$A$2:$A$623,$B15,评分与用量!$B$2:$B$623,$C$3,评分与用量!$C$2:$C$623,"人工负担证据",评分与用量!$D$2:$D$623,"首交后需处理任务数")=0,"",SUMIFS(评分与用量!$E$2:$E$623,评分与用量!$A$2:$A$623,$B15,评分与用量!$B$2:$B$623,$C$3,评分与用量!$C$2:$C$623,"人工负担证据",评分与用量!$D$2:$D$623,"首交后需处理任务数")) -> 0 | J15: =IF(SUMPRODUCT((运行记录!$A$2:$A$16=$B15)*(运行记录!$B$2:$B$16=$C$3)*ISNUMBER(运行记录!$P$2:$P$16))=0,"",SUMIFS(运行记录!$P$2:$P$16,运行记录!$A$2:$A$16,$B15,运行记录!$B$2:$B$16,$C$3)) -> 499485 | L15: =IF(COUNTIFS(运行记录!$A$2:$A$16,$B15,运行记录!$B$2:$B$16,$C$3)=0,"未运行",INDEX(运行记录!$E$2:$E$16,SUMPRODUCT((运行记录!$A$2:$A$16=$B15)*(运行记录!$B$2:$B$16=$C$3)*(ROW(运行记录!$A$2:$A$16)-1)))) -> Claude Code | N15: =IF(COUNTIFS(运行记录!$A$2:$A$16,$B15,运行记录!$B$2:$B$16,$C$3)=0,"未运行",INDEX(运行记录!$C$2:$C$16,SUMPRODUCT((运行记录!$A$2:$A$16=$B15)*(运行记录!$B$2:$B$16=$C$3)*(ROW(运行记录!$A$2:$A$16)-1)))) -> 失败 | BC15: =IF(SUMPRODUCT((运行记录!$A$2:$A$16=$B15)*(运行记录!$B$2:$B$16=$C$3)*ISNUMBER(运行记录!$Q$2:$Q$16))=0,"",SUMIFS(运行记录!$Q$2:$Q$16,运行记录!$A$2:$A$16,$B15,运行记录!$B$2:$B$16,$C$3)) -> 1.475652 | BD15: =IF(SUMPRODUCT((运行记录!$A$2:$A$16=$B15)*(运行记录!$B$2:$B$16=$C$3)*ISNUMBER(运行记录!$R$2:$R$16))=0,"",SUMIFS(运行记录!$R$2:$R$16,运行记录!$A$2:$A$16,$B15,运行记录!$B$2:$B$16,$C$3)) -> 1.475652 | BE15: =C15 | BF15: =D15
B16: Claude | C16: =IF(COUNTIFS(评分与用量!$A$2:$A$634,B16,评分与用量!$B$2:$B$634,"第一轮",评分与用量!$C$2:$C$634,"S分项")=0,"",SUMIFS(评分与用量!$E$2:$E$634,评分与用量!$A$2:$A$634,B16,评分与用量!$B$2:$B$634,"第一轮",评分与用量!$C$2:$C$634,"S分项")) -> 72 | D16: =IF(COUNTIFS(评分与用量!$A$2:$A$634,B16,评分与用量!$B$2:$B$634,"第二轮",评分与用量!$C$2:$C$634,"S分项")=0,"",SUMIFS(评分与用量!$E$2:$E$634,评分与用量!$A$2:$A$634,B16,评分与用量!$B$2:$B$634,"第二轮",评分与用量!$C$2:$C$634,"S分项")) | E16: =IF(SUMPRODUCT((运行记录!$A$2:$A$16=$B16)*(运行记录!$B$2:$B$16=$C$3)*ISNUMBER(运行记录!$M$2:$M$16))=0,"",SUMIFS(运行记录!$M$2:$M$16,运行记录!$A$2:$A$16,$B16,运行记录!$B$2:$B$16,$C$3)) | F16: =IF(OR(BC16="",BD16=""),"—",IF(ABS(BC16-BD16)<0.005,TEXT(BC16,"0.00"),TEXT(BC16,"0.00")&"–"&TEXT(BD16,"0.00"))) -> — | H16: =IF(COUNTIFS(行为记录!$A$2:$A$816,$B16,行为记录!$B$2:$B$816,$C$3,行为记录!$L$2:$L$816,"<>管理动作")=0,"",COUNTIFS(行为记录!$A$2:$A$816,$B16,行为记录!$B$2:$B$816,$C$3,行为记录!$L$2:$L$816,"确认无收益")/(COUNTIFS(行为记录!$A$2:$A$816,$B16,行为记录!$B$2:$B$816,$C$3,行为记录!$L$2:$L$816,"直接贡献交付")+COUNTIFS(行为记录!$A$2:$A$816,$B16,行为记录!$B$2:$B$816,$C$3,行为记录!$L$2:$L$816,"必要探索")+COUNTIFS(行为记录!$A$2:$A$816,$B16,行为记录!$B$2:$B$816,$C$3,行为记录!$L$2:$L$816,"确认无收益"))) | I16: =IF(COUNTIFS(评分与用量!$A$2:$A$623,$B16,评分与用量!$B$2:$B$623,$C$3,评分与用量!$C$2:$C$623,"人工负担证据",评分与用量!$D$2:$D$623,"首交后需处理任务数")=0,"",SUMIFS(评分与用量!$E$2:$E$623,评分与用量!$A$2:$A$623,$B16,评分与用量!$B$2:$B$623,$C$3,评分与用量!$C$2:$C$623,"人工负担证据",评分与用量!$D$2:$D$623,"首交后需处理任务数")) | J16: =IF(SUMPRODUCT((运行记录!$A$2:$A$16=$B16)*(运行记录!$B$2:$B$16=$C$3)*ISNUMBER(运行记录!$P$2:$P$16))=0,"",SUMIFS(运行记录!$P$2:$P$16,运行记录!$A$2:$A$16,$B16,运行记录!$B$2:$B$16,$C$3)) | L16: =IF(COUNTIFS(运行记录!$A$2:$A$16,$B16,运行记录!$B$2:$B$16,$C$3)=0,"未运行",INDEX(运行记录!$E$2:$E$16,SUMPRODUCT((运行记录!$A$2:$A$16=$B16)*(运行记录!$B$2:$B$16=$C$3)*(ROW(运行记录!$A$2:$A$16)-1)))) -> 未运行 | N16: =IF(COUNTIFS(运行记录!$A$2:$A$16,$B16,运行记录!$B$2:$B$16,$C$3)=0,"未运行",INDEX(运行记录!$C$2:$C$16,SUMPRODUCT((运行记录!$A$2:$A$16=$B16)*(运行记录!$B$2:$B$16=$C$3)*(ROW(运行记录!$A$2:$A$16)-1)))) -> 未运行 | BC16: =IF(SUMPRODUCT((运行记录!$A$2:$A$16=$B16)*(运行记录!$B$2:$B$16=$C$3)*ISNUMBER(运行记录!$Q$2:$Q$16))=0,"",SUMIFS(运行记录!$Q$2:$Q$16,运行记录!$A$2:$A$16,$B16,运行记录!$B$2:$B$16,$C$3)) | BD16: =IF(SUMPRODUCT((运行记录!$A$2:$A$16=$B16)*(运行记录!$B$2:$B$16=$C$3)*ISNUMBER(运行记录!$R$2:$R$16))=0,"",SUMIFS(运行记录!$R$2:$R$16,运行记录!$A$2:$A$16,$B16,运行记录!$B$2:$B$16,$C$3)) | BE16: =C16 -> 72 | BF16: =D16
B18: 比较说明 | E18: 评分标准：六维25项，共100分。六个系统两轮配对；Claude仅第一轮，Kimi未评分。
B19: 两轮 S 分数变化 · 六系统配对
B20: AI | D20: 第一轮 S | F20: 第二轮 S | H20: ΔS | J20: 第一轮分钟 | L20: 第二轮分钟 | N20: Δ分钟
B21: =B9 -> GPT | D21: =IF(C9="","",C9) -> 88 | F21: =IF(D9="","",D9) -> 98.5 | H21: =IF(OR(D21="",F21=""),"",IF(F21-D21=0,"0",IF(F21-D21>0,"+","-")&IF(MOD(ABS(F21-D21),1)=0,TEXT(ABS(F21-D21),"0"),TEXT(ABS(F21-D21),"0.##")))) -> +10.5 | J21: =IF(COUNTIFS(运行记录!$A$2:$A$16,B21,运行记录!$B$2:$B$16,"第一轮",运行记录!$H$2:$H$16,">0")=0,"",ROUND(SUMIFS(运行记录!$M$2:$M$16,运行记录!$A$2:$A$16,B21,运行记录!$B$2:$B$16,"第一轮"),1)) -> 14.6 | L21: =IF(COUNTIFS(运行记录!$A$2:$A$16,B21,运行记录!$B$2:$B$16,"第二轮",运行记录!$H$2:$H$16,">0")=0,"",ROUND(SUMIFS(运行记录!$M$2:$M$16,运行记录!$A$2:$A$16,B21,运行记录!$B$2:$B$16,"第二轮"),1)) -> 17.8 | N21: =IF(OR(J21="",L21=""),"",L21-J21) -> 3.2
B22: =B10 -> Grok | D22: =IF(C10="","",C10) -> 84.5 | F22: =IF(D10="","",D10) -> 85.25 | H22: =IF(OR(D22="",F22=""),"",IF(F22-D22=0,"0",IF(F22-D22>0,"+","-")&IF(MOD(ABS(F22-D22),1)=0,TEXT(ABS(F22-D22),"0"),TEXT(ABS(F22-D22),"0.##")))) -> +0.75 | J22: =IF(COUNTIFS(运行记录!$A$2:$A$16,B22,运行记录!$B$2:$B$16,"第一轮",运行记录!$H$2:$H$16,">0")=0,"",ROUND(SUMIFS(运行记录!$M$2:$M$16,运行记录!$A$2:$A$16,B22,运行记录!$B$2:$B$16,"第一轮"),1)) -> 10.1 | L22: =IF(COUNTIFS(运行记录!$A$2:$A$16,B22,运行记录!$B$2:$B$16,"第二轮",运行记录!$H$2:$H$16,">0")=0,"",ROUND(SUMIFS(运行记录!$M$2:$M$16,运行记录!$A$2:$A$16,B22,运行记录!$B$2:$B$16,"第二轮"),1)) -> 11.7 | N22: =IF(OR(J22="",L22=""),"",L22-J22) -> 1.6
B23: =B11 -> DeepSeek | D23: =IF(C11="","",C11) -> 76.5 | F23: =IF(D11="","",D11) -> 87.25 | H23: =IF(OR(D23="",F23=""),"",IF(F23-D23=0,"0",IF(F23-D23>0,"+","-")&IF(MOD(ABS(F23-D23),1)=0,TEXT(ABS(F23-D23),"0"),TEXT(ABS(F23-D23),"0.##")))) -> +10.75 | J23: =IF(COUNTIFS(运行记录!$A$2:$A$16,B23,运行记录!$B$2:$B$16,"第一轮",运行记录!$H$2:$H$16,">0")=0,"",ROUND(SUMIFS(运行记录!$M$2:$M$16,运行记录!$A$2:$A$16,B23,运行记录!$B$2:$B$16,"第一轮"),1)) -> 32.4 | L23: =IF(COUNTIFS(运行记录!$A$2:$A$16,B23,运行记录!$B$2:$B$16,"第二轮",运行记录!$H$2:$H$16,">0")=0,"",ROUND(SUMIFS(运行记录!$M$2:$M$16,运行记录!$A$2:$A$16,B23,运行记录!$B$2:$B$16,"第二轮"),1)) -> 21.7 | N23: =IF(OR(J23="",L23=""),"",L23-J23) -> -10.7
B24: =B12 -> GLM | D24: =IF(C12="","",C12) -> 74 | F24: =IF(D12="","",D12) -> 81 | H24: =IF(OR(D24="",F24=""),"",IF(F24-D24=0,"0",IF(F24-D24>0,"+","-")&IF(MOD(ABS(F24-D24),1)=0,TEXT(ABS(F24-D24),"0"),TEXT(ABS(F24-D24),"0.##")))) -> +7 | J24: =IF(COUNTIFS(运行记录!$A$2:$A$16,B24,运行记录!$B$2:$B$16,"第一轮",运行记录!$H$2:$H$16,">0")=0,"",ROUND(SUMIFS(运行记录!$M$2:$M$16,运行记录!$A$2:$A$16,B24,运行记录!$B$2:$B$16,"第一轮"),1)) -> 5.5 | L24: =IF(COUNTIFS(运行记录!$A$2:$A$16,B24,运行记录!$B$2:$B$16,"第二轮",运行记录!$H$2:$H$16,">0")=0,"",ROUND(SUMIFS(运行记录!$M$2:$M$16,运行记录!$A$2:$A$16,B24,运行记录!$B$2:$B$16,"第二轮"),1)) -> 9.6 | N24: =IF(OR(J24="",L24=""),"",L24-J24) -> 4.1
B25: =B13 -> Qwen | D25: =IF(C13="","",C13) -> 67.5 | F25: =IF(D13="","",D13) -> 75.25 | H25: =IF(OR(D25="",F25=""),"",IF(F25-D25=0,"0",IF(F25-D25>0,"+","-")&IF(MOD(ABS(F25-D25),1)=0,TEXT(ABS(F25-D25),"0"),TEXT(ABS(F25-D25),"0.##")))) -> +7.75 | J25: =IF(COUNTIFS(运行记录!$A$2:$A$16,B25,运行记录!$B$2:$B$16,"第一轮",运行记录!$H$2:$H$16,">0")=0,"",ROUND(SUMIFS(运行记录!$M$2:$M$16,运行记录!$A$2:$A$16,B25,运行记录!$B$2:$B$16,"第一轮"),1)) -> 14.3 | L25: =IF(COUNTIFS(运行记录!$A$2:$A$16,B25,运行记录!$B$2:$B$16,"第二轮",运行记录!$H$2:$H$16,">0")=0,"",ROUND(SUMIFS(运行记录!$M$2:$M$16,运行记录!$A$2:$A$16,B25,运行记录!$B$2:$B$16,"第二轮"),1)) -> 60.2 | N25: =IF(OR(J25="",L25=""),"",L25-J25) -> 45.9
B26: =B14 -> Gemini | D26: =IF(C14="","",C14) -> 39.5 | F26: =IF(D14="","",D14) -> 59.5 | H26: =IF(OR(D26="",F26=""),"",IF(F26-D26=0,"0",IF(F26-D26>0,"+","-")&IF(MOD(ABS(F26-D26),1)=0,TEXT(ABS(F26-D26),"0"),TEXT(ABS(F26-D26),"0.##")))) -> +20 | J26: =IF(COUNTIFS(运行记录!$A$2:$A$16,B26,运行记录!$B$2:$B$16,"第一轮",运行记录!$H$2:$H$16,">0")=0,"",ROUND(SUMIFS(运行记录!$M$2:$M$16,运行记录!$A$2:$A$16,B26,运行记录!$B$2:$B$16,"第一轮"),1)) -> 15.3 | L26: =IF(COUNTIFS(运行记录!$A$2:$A$16,B26,运行记录!$B$2:$B$16,"第二轮",运行记录!$H$2:$H$16,">0")=0,"",ROUND(SUMIFS(运行记录!$M$2:$M$16,运行记录!$A$2:$A$16,B26,运行记录!$B$2:$B$16,"第二轮"),1)) -> 6.1 | N26: =IF(OR(J26="",L26=""),"",L26-J26) -> -9.2
P28: 比较说明
B29: 六系统配对 · S 六维变化 | P29: 比较范围 | S29: GPT、Grok、DeepSeek、GLM、Qwen、Gemini 六系统两轮等权。
B30: 评分维度 | E30: 满分 | G30: 第一轮均分 | I30: 第二轮均分 | K30: 平均增量 | M30: 分项增量占比
B31: 数据基础与问题定义 | E31: 15 | G31: =(SUMIFS(评分与用量!$E$2:$E$634,评分与用量!$A$2:$A$634,"GPT",评分与用量!$B$2:$B$634,"第一轮",评分与用量!$C$2:$C$634,"S分项",评分与用量!$J$2:$J$634,"A*")+SUMIFS(评分与用量!$E$2:$E$634,评分与用量!$A$2:$A$634,"Grok",评分与用量!$B$2:$B$634,"第一轮",评分与用量!$C$2:$C$634,"S分项",评分与用量!$J$2:$J$634,"A*")+SUMIFS(评分与用量!$E$2:$E$634,评分与用量!$A$2:$A$634,"DeepSeek",评分与用量!$B$2:$B$634,"第一轮",评分与用量!$C$2:$C$634,"S分项",评分与用量!$J$2:$J$634,"A*")+SUMIFS(评分与用量!$E$2:$E$634,评分与用量!$A$2:$A$634,"GLM",评分与用量!$B$2:$B$634,"第一轮",评分与用量!$C$2:$C$634,"S分项",评分与用量!$J$2:$J$634,"A*")+SUMIFS(评分与用量!$E$2:$E$634,评分与用量!$A$2:$A$634,"Qwen",评分与用量!$B$2:$B$634,"第一轮",评分与用量!$C$2:$C$634,"S分项",评分与用量!$J$2:$J$634,"A*")+SUMIFS(评分与用量!$E$2:$E$634,评分与用量!$A$2:$A$634,"Gemini",评分与用量!$B$2:$B$634,"第一轮",评分与用量!$C$2:$C$634,"S分项",评分与用量!$J$2:$J$634,"A*"))/6 -> 11.75 | I31: =(SUMIFS(评分与用量!$E$2:$E$634,评分与用量!$A$2:$A$634,"GPT",评分与用量!$B$2:$B$634,"第二轮",评分与用量!$C$2:$C$634,"S分项",评分与用量!$J$2:$J$634,"A*")+SUMIFS(评分与用量!$E$2:$E$634,评分与用量!$A$2:$A$634,"Grok",评分与用量!$B$2:$B$634,"第二轮",评分与用量!$C$2:$C$634,"S分项",评分与用量!$J$2:$J$634,"A*")+SUMIFS(评分与用量!$E$2:$E$634,评分与用量!$A$2:$A$634,"DeepSeek",评分与用量!$B$2:$B$634,"第二轮",评分与用量!$C$2:$C$634,"S分项",评分与用量!$J$2:$J$634,"A*")+SUMIFS(评分与用量!$E$2:$E$634,评分与用量!$A$2:$A$634,"GLM",评分与用量!$B$2:$B$634,"第二轮",评分与用量!$C$2:$C$634,"S分项",评分与用量!$J$2:$J$634,"A*")+SUMIFS(评分与用量!$E$2:$E$634,评分与用量!$A$2:$A$634,"Qwen",评分与用量!$B$2:$B$634,"第二轮",评分与用量!$C$2:$C$634,"S分项",评分与用量!$J$2:$J$634,"A*")+SUMIFS(评分与用量!$E$2:$E$634,评分与用量!$A$2:$A$634,"Gemini",评分与用量!$B$2:$B$634,"第二轮",评分与用量!$C$2:$C$634,"S分项",评分与用量!$J$2:$J$634,"A*"))/6 -> 13.333333 | K31: =I31-G31 -> 1.5833333 | M31: =IFERROR(K31/$K$37,"") -> 0.16740088 | P31: 计算方法 | S31: 逐项评分可在“评分细项”和“评分与用量”复算。
B32: 证据与计算 | E32: 20 | G32: =(SUMIFS(评分与用量!$E$2:$E$634,评分与用量!$A$2:$A$634,"GPT",评分与用量!$B$2:$B$634,"第一轮",评分与用量!$C$2:$C$634,"S分项",评分与用量!$J$2:$J$634,"B*")+SUMIFS(评分与用量!$E$2:$E$634,评分与用量!$A$2:$A$634,"Grok",评分与用量!$B$2:$B$634,"第一轮",评分与用量!$C$2:$C$634,"S分项",评分与用量!$J$2:$J$634,"B*")+SUMIFS(评分与用量!$E$2:$E$634,评分与用量!$A$2:$A$634,"DeepSeek",评分与用量!$B$2:$B$634,"第一轮",评分与用量!$C$2:$C$634,"S分项",评分与用量!$J$2:$J$634,"B*")+SUMIFS(评分与用量!$E$2:$E$634,评分与用量!$A$2:$A$634,"GLM",评分与用量!$B$2:$B$634,"第一轮",评分与用量!$C$2:$C$634,"S分项",评分与用量!$J$2:$J$634,"B*")+SUMIFS(评分与用量!$E$2:$E$634,评分与用量!$A$2:$A$634,"Qwen",评分与用量!$B$2:$B$634,"第一轮",评分与用量!$C$2:$C$634,"S分项",评分与用量!$J$2:$J$634,"B*")+SUMIFS(评分与用量!$E$2:$E$634,评分与用量!$A$2:$A$634,"Gemini",评分与用量!$B$2:$B$634,"第一轮",评分与用量!$C$2:$C$634,"S分项",评分与用量!$J$2:$J$634,"B*"))/6 -> 14.958333 | I32: =(SUMIFS(评分与用量!$E$2:$E$634,评分与用量!$A$2:$A$634,"GPT",评分与用量!$B$2:$B$634,"第二轮",评分与用量!$C$2:$C$634,"S分项",评分与用量!$J$2:$J$634,"B*")+SUMIFS(评分与用量!$E$2:$E$634,评分与用量!$A$2:$A$634,"Grok",评分与用量!$B$2:$B$634,"第二轮",评分与用量!$C$2:$C$634,"S分项",评分与用量!$J$2:$J$634,"B*")+SUMIFS(评分与用量!$E$2:$E$634,评分与用量!$A$2:$A$634,"DeepSeek",评分与用量!$B$2:$B$634,"第二轮",评分与用量!$C$2:$C$634,"S分项",评分与用量!$J$2:$J$634,"B*")+SUMIFS(评分与用量!$E$2:$E$634,评分与用量!$A$2:$A$634,"GLM",评分与用量!$B$2:$B$634,"第二轮",评分与用量!$C$2:$C$634,"S分项",评分与用量!$J$2:$J$634,"B*")+SUMIFS(评分与用量!$E$2:$E$634,评分与用量!$A$2:$A$634,"Qwen",评分与用量!$B$2:$B$634,"第二轮",评分与用量!$C$2:$C$634,"S分项",评分与用量!$J$2:$J$634,"B*")+SUMIFS(评分与用量!$E$2:$E$634,评分与用量!$A$2:$A$634,"Gemini",评分与用量!$B$2:$B$634,"第二轮",评分与用量!$C$2:$C$634,"S分项",评分与用量!$J$2:$J$634,"B*"))/6 -> 16 | K32: =I32-G32 -> 1.0416667 | M32: =IFERROR(K32/$K$37,"") -> 0.11013216
B33: 调查深度与判断 | E33: 20 | G33: =(SUMIFS(评分与用量!$E$2:$E$634,评分与用量!$A$2:$A$634,"GPT",评分与用量!$B$2:$B$634,"第一轮",评分与用量!$C$2:$C$634,"S分项",评分与用量!$J$2:$J$634,"C*")+SUMIFS(评分与用量!$E$2:$E$634,评分与用量!$A$2:$A$634,"Grok",评分与用量!$B$2:$B$634,"第一轮",评分与用量!$C$2:$C$634,"S分项",评分与用量!$J$2:$J$634,"C*")+SUMIFS(评分与用量!$E$2:$E$634,评分与用量!$A$2:$A$634,"DeepSeek",评分与用量!$B$2:$B$634,"第一轮",评分与用量!$C$2:$C$634,"S分项",评分与用量!$J$2:$J$634,"C*")+SUMIFS(评分与用量!$E$2:$E$634,评分与用量!$A$2:$A$634,"GLM",评分与用量!$B$2:$B$634,"第一轮",评分与用量!$C$2:$C$634,"S分项",评分与用量!$J$2:$J$634,"C*")+SUMIFS(评分与用量!$E$2:$E$634,评分与用量!$A$2:$A$634,"Qwen",评分与用量!$B$2:$B$634,"第一轮",评分与用量!$C$2:$C$634,"S分项",评分与用量!$J$2:$J$634,"C*")+SUMIFS(评分与用量!$E$2:$E$634,评分与用量!$A$2:$A$634,"Gemini",评分与用量!$B$2:$B$634,"第一轮",评分与用量!$C$2:$C$634,"S分项",评分与用量!$J$2:$J$634,"C*"))/6 -> 12.375 | I33: =(SUMIFS(评分与用量!$E$2:$E$634,评分与用量!$A$2:$A$634,"GPT",评分与用量!$B$2:$B$634,"第二轮",评分与用量!$C$2:$C$634,"S分项",评分与用量!$J$2:$J$634,"C*")+SUMIFS(评分与用量!$E$2:$E$634,评分与用量!$A$2:$A$634,"Grok",评分与用量!$B$2:$B$634,"第二轮",评分与用量!$C$2:$C$634,"S分项",评分与用量!$J$2:$J$634,"C*")+SUMIFS(评分与用量!$E$2:$E$634,评分与用量!$A$2:$A$634,"DeepSeek",评分与用量!$B$2:$B$634,"第二轮",评分与用量!$C$2:$C$634,"S分项",评分与用量!$J$2:$J$634,"C*")+SUMIFS(评分与用量!$E$2:$E$634,评分与用量!$A$2:$A$634,"GLM",评分与用量!$B$2:$B$634,"第二轮",评分与用量!$C$2:$C$634,"S分项",评分与用量!$J$2:$J$634,"C*")+SUMIFS(评分与用量!$E$2:$E$634,评分与用量!$A$2:$A$634,"Qwen",评分与用量!$B$2:$B$634,"第二轮",评分与用量!$C$2:$C$634,"S分项",评分与用量!$J$2:$J$634,"C*")+SUMIFS(评分与用量!$E$2:$E$634,评分与用量!$A$2:$A$634,"Gemini",评分与用量!$B$2:$B$634,"第二轮",评分与用量!$C$2:$C$634,"S分项",评分与用量!$J$2:$J$634,"C*"))/6 -> 17.041667 | K33: =I33-G33 -> 4.6666667 | M33: =IFERROR(K33/$K$37,"") -> 0.49339207 | P33: 主要变化 | S33: 调查深度与判断平均提高4.67分，占总增量约49.3%。
B34: 人工复现与维护 | E34: 25 | G34: =(SUMIFS(评分与用量!$E$2:$E$634,评分与用量!$A$2:$A$634,"GPT",评分与用量!$B$2:$B$634,"第一轮",评分与用量!$C$2:$C$634,"S分项",评分与用量!$J$2:$J$634,"D*")+SUMIFS(评分与用量!$E$2:$E$634,评分与用量!$A$2:$A$634,"Grok",评分与用量!$B$2:$B$634,"第一轮",评分与用量!$C$2:$C$634,"S分项",评分与用量!$J$2:$J$634,"D*")+SUMIFS(评分与用量!$E$2:$E$634,评分与用量!$A$2:$A$634,"DeepSeek",评分与用量!$B$2:$B$634,"第一轮",评分与用量!$C$2:$C$634,"S分项",评分与用量!$J$2:$J$634,"D*")+SUMIFS(评分与用量!$E$2:$E$634,评分与用量!$A$2:$A$634,"GLM",评分与用量!$B$2:$B$634,"第一轮",评分与用量!$C$2:$C$634,"S分项",评分与用量!$J$2:$J$634,"D*")+SUMIFS(评分与用量!$E$2:$E$634,评分与用量!$A$2:$A$634,"Qwen",评分与用量!$B$2:$B$634,"第一轮",评分与用量!$C$2:$C$634,"S分项",评分与用量!$J$2:$J$634,"D*")+SUMIFS(评分与用量!$E$2:$E$634,评分与用量!$A$2:$A$634,"Gemini",评分与用量!$B$2:$B$634,"第一轮",评分与用量!$C$2:$C$634,"S分项",评分与用量!$J$2:$J$634,"D*"))/6 -> 17.083333 | I34: =(SUMIFS(评分与用量!$E$2:$E$634,评分与用量!$A$2:$A$634,"GPT",评分与用量!$B$2:$B$634,"第二轮",评分与用量!$C$2:$C$634,"S分项",评分与用量!$J$2:$J$634,"D*")+SUMIFS(评分与用量!$E$2:$E$634,评分与用量!$A$2:$A$634,"Grok",评分与用量!$B$2:$B$634,"第二轮",评分与用量!$C$2:$C$634,"S分项",评分与用量!$J$2:$J$634,"D*")+SUMIFS(评分与用量!$E$2:$E$634,评分与用量!$A$2:$A$634,"DeepSeek",评分与用量!$B$2:$B$634,"第二轮",评分与用量!$C$2:$C$634,"S分项",评分与用量!$J$2:$J$634,"D*")+SUMIFS(评分与用量!$E$2:$E$634,评分与用量!$A$2:$A$634,"GLM",评分与用量!$B$2:$B$634,"第二轮",评分与用量!$C$2:$C$634,"S分项",评分与用量!$J$2:$J$634,"D*")+SUMIFS(评分与用量!$E$2:$E$634,评分与用量!$A$2:$A$634,"Qwen",评分与用量!$B$2:$B$634,"第二轮",评分与用量!$C$2:$C$634,"S分项",评分与用量!$J$2:$J$634,"D*")+SUMIFS(评分与用量!$E$2:$E$634,评分与用量!$A$2:$A$634,"Gemini",评分与用量!$B$2:$B$634,"第二轮",评分与用量!$C$2:$C$634,"S分项",评分与用量!$J$2:$J$634,"D*"))/6 -> 18.541667 | K34: =I34-G34 -> 1.4583333 | M34: =IFERROR(K34/$K$37,"") -> 0.15418502
B35: 成品实际可用性 | E35: 10 | G35: =(SUMIFS(评分与用量!$E$2:$E$634,评分与用量!$A$2:$A$634,"GPT",评分与用量!$B$2:$B$634,"第一轮",评分与用量!$C$2:$C$634,"S分项",评分与用量!$J$2:$J$634,"E*")+SUMIFS(评分与用量!$E$2:$E$634,评分与用量!$A$2:$A$634,"Grok",评分与用量!$B$2:$B$634,"第一轮",评分与用量!$C$2:$C$634,"S分项",评分与用量!$J$2:$J$634,"E*")+SUMIFS(评分与用量!$E$2:$E$634,评分与用量!$A$2:$A$634,"DeepSeek",评分与用量!$B$2:$B$634,"第一轮",评分与用量!$C$2:$C$634,"S分项",评分与用量!$J$2:$J$634,"E*")+SUMIFS(评分与用量!$E$2:$E$634,评分与用量!$A$2:$A$634,"GLM",评分与用量!$B$2:$B$634,"第一轮",评分与用量!$C$2:$C$634,"S分项",评分与用量!$J$2:$J$634,"E*")+SUMIFS(评分与用量!$E$2:$E$634,评分与用量!$A$2:$A$634,"Qwen",评分与用量!$B$2:$B$634,"第一轮",评分与用量!$C$2:$C$634,"S分项",评分与用量!$J$2:$J$634,"E*")+SUMIFS(评分与用量!$E$2:$E$634,评分与用量!$A$2:$A$634,"Gemini",评分与用量!$B$2:$B$634,"第一轮",评分与用量!$C$2:$C$634,"S分项",评分与用量!$J$2:$J$634,"E*"))/6 -> 6.9166667 | I35: =(SUMIFS(评分与用量!$E$2:$E$634,评分与用量!$A$2:$A$634,"GPT",评分与用量!$B$2:$B$634,"第二轮",评分与用量!$C$2:$C$634,"S分项",评分与用量!$J$2:$J$634,"E*")+SUMIFS(评分与用量!$E$2:$E$634,评分与用量!$A$2:$A$634,"Grok",评分与用量!$B$2:$B$634,"第二轮",评分与用量!$C$2:$C$634,"S分项",评分与用量!$J$2:$J$634,"E*")+SUMIFS(评分与用量!$E$2:$E$634,评分与用量!$A$2:$A$634,"DeepSeek",评分与用量!$B$2:$B$634,"第二轮",评分与用量!$C$2:$C$634,"S分项",评分与用量!$J$2:$J$634,"E*")+SUMIFS(评分与用量!$E$2:$E$634,评分与用量!$A$2:$A$634,"GLM",评分与用量!$B$2:$B$634,"第二轮",评分与用量!$C$2:$C$634,"S分项",评分与用量!$J$2:$J$634,"E*")+SUMIFS(评分与用量!$E$2:$E$634,评分与用量!$A$2:$A$634,"Qwen",评分与用量!$B$2:$B$634,"第二轮",评分与用量!$C$2:$C$634,"S分项",评分与用量!$J$2:$J$634,"E*")+SUMIFS(评分与用量!$E$2:$E$634,评分与用量!$A$2:$A$634,"Gemini",评分与用量!$B$2:$B$634,"第二轮",评分与用量!$C$2:$C$634,"S分项",评分与用量!$J$2:$J$634,"E*"))/6 -> 7.4583333 | K35: =I35-G35 -> 0.54166667 | M35: =IFERROR(K35/$K$37,"") -> 0.057268722 | P35: 评分说明 | S35: 评分标准；六系统按同一口径评分。
B36: 自主性与资源纪律 | E36: 10 | G36: =(SUMIFS(评分与用量!$E$2:$E$634,评分与用量!$A$2:$A$634,"GPT",评分与用量!$B$2:$B$634,"第一轮",评分与用量!$C$2:$C$634,"S分项",评分与用量!$J$2:$J$634,"F*")+SUMIFS(评分与用量!$E$2:$E$634,评分与用量!$A$2:$A$634,"Grok",评分与用量!$B$2:$B$634,"第一轮",评分与用量!$C$2:$C$634,"S分项",评分与用量!$J$2:$J$634,"F*")+SUMIFS(评分与用量!$E$2:$E$634,评分与用量!$A$2:$A$634,"DeepSeek",评分与用量!$B$2:$B$634,"第一轮",评分与用量!$C$2:$C$634,"S分项",评分与用量!$J$2:$J$634,"F*")+SUMIFS(评分与用量!$E$2:$E$634,评分与用量!$A$2:$A$634,"GLM",评分与用量!$B$2:$B$634,"第一轮",评分与用量!$C$2:$C$634,"S分项",评分与用量!$J$2:$J$634,"F*")+SUMIFS(评分与用量!$E$2:$E$634,评分与用量!$A$2:$A$634,"Qwen",评分与用量!$B$2:$B$634,"第一轮",评分与用量!$C$2:$C$634,"S分项",评分与用量!$J$2:$J$634,"F*")+SUMIFS(评分与用量!$E$2:$E$634,评分与用量!$A$2:$A$634,"Gemini",评分与用量!$B$2:$B$634,"第一轮",评分与用量!$C$2:$C$634,"S分项",评分与用量!$J$2:$J$634,"F*"))/6 -> 8.5833333 | I36: =(SUMIFS(评分与用量!$E$2:$E$634,评分与用量!$A$2:$A$634,"GPT",评分与用量!$B$2:$B$634,"第二轮",评分与用量!$C$2:$C$634,"S分项",评分与用量!$J$2:$J$634,"F*")+SUMIFS(评分与用量!$E$2:$E$634,评分与用量!$A$2:$A$634,"Grok",评分与用量!$B$2:$B$634,"第二轮",评分与用量!$C$2:$C$634,"S分项",评分与用量!$J$2:$J$634,"F*")+SUMIFS(评分与用量!$E$2:$E$634,评分与用量!$A$2:$A$634,"DeepSeek",评分与用量!$B$2:$B$634,"第二轮",评分与用量!$C$2:$C$634,"S分项",评分与用量!$J$2:$J$634,"F*")+SUMIFS(评分与用量!$E$2:$E$634,评分与用量!$A$2:$A$634,"GLM",评分与用量!$B$2:$B$634,"第二轮",评分与用量!$C$2:$C$634,"S分项",评分与用量!$J$2:$J$634,"F*")+SUMIFS(评分与用量!$E$2:$E$634,评分与用量!$A$2:$A$634,"Qwen",评分与用量!$B$2:$B$634,"第二轮",评分与用量!$C$2:$C$634,"S分项",评分与用量!$J$2:$J$634,"F*")+SUMIFS(评分与用量!$E$2:$E$634,评分与用量!$A$2:$A$634,"Gemini",评分与用量!$B$2:$B$634,"第二轮",评分与用量!$C$2:$C$634,"S分项",评分与用量!$J$2:$J$634,"F*"))/6 -> 8.75 | K36: =I36-G36 -> 0.16666667 | M36: =IFERROR(K36/$K$37,"") -> 0.017621145
B37: 六维合计 | E37: 100 | G37: =SUM(G31:G36) -> 71.666667 | I37: =SUM(I31:I36) -> 81.125 | K37: =SUM(K31:K36) -> 9.4583333 | M37: =SUM(M31:M36) -> 1

Sheet 评分细项
A1: =$B$2&" | 评分细项 · 评分标准" -> GPT | 评分细项 · 评分标准
A2: AI | B2: GPT | C2: ▼
A4: 编号 | B4: 评分项 | C4: 满分 | D4: 第一轮 | E4: 第二轮 | F4: 分差 | H4: 编号 | I4: 评分项 | J4: 满分 | K4: 第一轮 | L4: 第二轮 | M4: 分差
A5: A 数据基础与问题定义 · 15分 | H5: D 人工复现与维护 · 25分
A6: A1 | B6: 粒度与语义 | C6: 4 | D6: =IF(COUNTIFS(评分与用量!$A$2:$A$634,$B$2,评分与用量!$B$2:$B$634,"第一轮",评分与用量!$C$2:$C$634,"S分项",评分与用量!$J$2:$J$634,"A1")=0,"",SUMIFS(评分与用量!$E$2:$E$634,评分与用量!$A$2:$A$634,$B$2,评分与用量!$B$2:$B$634,"第一轮",评分与用量!$C$2:$C$634,"S分项",评分与用量!$J$2:$J$634,"A1")) -> 4 | E6: =IF(COUNTIFS(评分与用量!$A$2:$A$634,$B$2,评分与用量!$B$2:$B$634,"第二轮",评分与用量!$C$2:$C$634,"S分项",评分与用量!$J$2:$J$634,"A1")=0,"",SUMIFS(评分与用量!$E$2:$E$634,评分与用量!$A$2:$A$634,$B$2,评分与用量!$B$2:$B$634,"第二轮",评分与用量!$C$2:$C$634,"S分项",评分与用量!$J$2:$J$634,"A1")) -> 4 | F6: =IF(OR(D6="",E6=""),"",IF(E6-D6=0,"0",IF(E6-D6>0,"+","-")&IF(MOD(ABS(E6-D6),1)=0,TEXT(ABS(E6-D6),"0"),TEXT(ABS(E6-D6),"0.##")))) -> 0 | H6: D1 | I6: 阅读入口与步骤 | J6: 4 | K6: =IF(COUNTIFS(评分与用量!$A$2:$A$634,$B$2,评分与用量!$B$2:$B$634,"第一轮",评分与用量!$C$2:$C$634,"S分项",评分与用量!$J$2:$J$634,"D1")=0,"",SUMIFS(评分与用量!$E$2:$E$634,评分与用量!$A$2:$A$634,$B$2,评分与用量!$B$2:$B$634,"第一轮",评分与用量!$C$2:$C$634,"S分项",评分与用量!$J$2:$J$634,"D1")) -> 4 | L6: =IF(COUNTIFS(评分与用量!$A$2:$A$634,$B$2,评分与用量!$B$2:$B$634,"第二轮",评分与用量!$C$2:$C$634,"S分项",评分与用量!$J$2:$J$634,"D1")=0,"",SUMIFS(评分与用量!$E$2:$E$634,评分与用量!$A$2:$A$634,$B$2,评分与用量!$B$2:$B$634,"第二轮",评分与用量!$C$2:$C$634,"S分项",评分与用量!$J$2:$J$634,"D1")) -> 4 | M6: =IF(OR(K6="",L6=""),"",IF(L6-K6=0,"0",IF(L6-K6>0,"+","-")&IF(MOD(ABS(L6-K6),1)=0,TEXT(ABS(L6-K6),"0"),TEXT(ABS(L6-K6),"0.##")))) -> 0
A7: A2 | B7: 数据质量判断 | C7: 4 | D7: =IF(COUNTIFS(评分与用量!$A$2:$A$634,$B$2,评分与用量!$B$2:$B$634,"第一轮",评分与用量!$C$2:$C$634,"S分项",评分与用量!$J$2:$J$634,"A2")=0,"",SUMIFS(评分与用量!$E$2:$E$634,评分与用量!$A$2:$A$634,$B$2,评分与用量!$B$2:$B$634,"第一轮",评分与用量!$C$2:$C$634,"S分项",评分与用量!$J$2:$J$634,"A2")) -> 4 | E7: =IF(COUNTIFS(评分与用量!$A$2:$A$634,$B$2,评分与用量!$B$2:$B$634,"第二轮",评分与用量!$C$2:$C$634,"S分项",评分与用量!$J$2:$J$634,"A2")=0,"",SUMIFS(评分与用量!$E$2:$E$634,评分与用量!$A$2:$A$634,$B$2,评分与用量!$B$2:$B$634,"第二轮",评分与用量!$C$2:$C$634,"S分项",评分与用量!$J$2:$J$634,"A2")) -> 4 | F7: =IF(OR(D7="",E7=""),"",IF(E7-D7=0,"0",IF(E7-D7>0,"+","-")&IF(MOD(ABS(E7-D7),1)=0,TEXT(ABS(E7-D7),"0"),TEXT(ABS(E7-D7),"0.##")))) -> 0 | H7: D2 | I7: 过程可理解 | J7: 6 | K7: =IF(COUNTIFS(评分与用量!$A$2:$A$634,$B$2,评分与用量!$B$2:$B$634,"第一轮",评分与用量!$C$2:$C$634,"S分项",评分与用量!$J$2:$J$634,"D2")=0,"",SUMIFS(评分与用量!$E$2:$E$634,评分与用量!$A$2:$A$634,$B$2,评分与用量!$B$2:$B$634,"第一轮",评分与用量!$C$2:$C$634,"S分项",评分与用量!$J$2:$J$634,"D2")) -> 4.5 | L7: =IF(COUNTIFS(评分与用量!$A$2:$A$634,$B$2,评分与用量!$B$2:$B$634,"第二轮",评分与用量!$C$2:$C$634,"S分项",评分与用量!$J$2:$J$634,"D2")=0,"",SUMIFS(评分与用量!$E$2:$E$634,评分与用量!$A$2:$A$634,$B$2,评分与用量!$B$2:$B$634,"第二轮",评分与用量!$C$2:$C$634,"S分项",评分与用量!$J$2:$J$634,"D2")) -> 6 | M7: =IF(OR(K7="",L7=""),"",IF(L7-K7=0,"0",IF(L7-K7>0,"+","-")&IF(MOD(ABS(L7-K7),1)=0,TEXT(ABS(L7-K7),"0"),TEXT(ABS(L7-K7),"0.##")))) -> +1.5
A8: A3 | B8: 问题可回答性 | C8: 3 | D8: =IF(COUNTIFS(评分与用量!$A$2:$A$634,$B$2,评分与用量!$B$2:$B$634,"第一轮",评分与用量!$C$2:$C$634,"S分项",评分与用量!$J$2:$J$634,"A3")=0,"",SUMIFS(评分与用量!$E$2:$E$634,评分与用量!$A$2:$A$634,$B$2,评分与用量!$B$2:$B$634,"第一轮",评分与用量!$C$2:$C$634,"S分项",评分与用量!$J$2:$J$634,"A3")) -> 3 | E8: =IF(COUNTIFS(评分与用量!$A$2:$A$634,$B$2,评分与用量!$B$2:$B$634,"第二轮",评分与用量!$C$2:$C$634,"S分项",评分与用量!$J$2:$J$634,"A3")=0,"",SUMIFS(评分与用量!$E$2:$E$634,评分与用量!$A$2:$A$634,$B$2,评分与用量!$B$2:$B$634,"第二轮",评分与用量!$C$2:$C$634,"S分项",评分与用量!$J$2:$J$634,"A3")) -> 3 | F8: =IF(OR(D8="",E8=""),"",IF(E8-D8=0,"0",IF(E8-D8>0,"+","-")&IF(MOD(ABS(E8-D8),1)=0,TEXT(ABS(E8-D8),"0"),TEXT(ABS(E8-D8),"0.##")))) -> 0 | H8: D3 | I8: 结果可重做 | J8: 6 | K8: =IF(COUNTIFS(评分与用量!$A$2:$A$634,$B$2,评分与用量!$B$2:$B$634,"第一轮",评分与用量!$C$2:$C$634,"S分项",评分与用量!$J$2:$J$634,"D3")=0,"",SUMIFS(评分与用量!$E$2:$E$634,评分与用量!$A$2:$A$634,$B$2,评分与用量!$B$2:$B$634,"第一轮",评分与用量!$C$2:$C$634,"S分项",评分与用量!$J$2:$J$634,"D3")) -> 6 | L8: =IF(COUNTIFS(评分与用量!$A$2:$A$634,$B$2,评分与用量!$B$2:$B$634,"第二轮",评分与用量!$C$2:$C$634,"S分项",评分与用量!$J$2:$J$634,"D3")=0,"",SUMIFS(评分与用量!$E$2:$E$634,评分与用量!$A$2:$A$634,$B$2,评分与用量!$B$2:$B$634,"第二轮",评分与用量!$C$2:$C$634,"S分项",评分与用量!$J$2:$J$634,"D3")) -> 6 | M8: =IF(OR(K8="",L8=""),"",IF(L8-K8=0,"0",IF(L8-K8>0,"+","-")&IF(MOD(ABS(L8-K8),1)=0,TEXT(ABS(L8-K8),"0"),TEXT(ABS(L8-K8),"0.##")))) -> 0
A9: A4 | B9: 问题优先级 | C9: 4 | D9: =IF(COUNTIFS(评分与用量!$A$2:$A$634,$B$2,评分与用量!$B$2:$B$634,"第一轮",评分与用量!$C$2:$C$634,"S分项",评分与用量!$J$2:$J$634,"A4")=0,"",SUMIFS(评分与用量!$E$2:$E$634,评分与用量!$A$2:$A$634,$B$2,评分与用量!$B$2:$B$634,"第一轮",评分与用量!$C$2:$C$634,"S分项",评分与用量!$J$2:$J$634,"A4")) -> 3 | E9: =IF(COUNTIFS(评分与用量!$A$2:$A$634,$B$2,评分与用量!$B$2:$B$634,"第二轮",评分与用量!$C$2:$C$634,"S分项",评分与用量!$J$2:$J$634,"A4")=0,"",SUMIFS(评分与用量!$E$2:$E$634,评分与用量!$A$2:$A$634,$B$2,评分与用量!$B$2:$B$634,"第二轮",评分与用量!$C$2:$C$634,"S分项",评分与用量!$J$2:$J$634,"A4")) -> 4 | F9: =IF(OR(D9="",E9=""),"",IF(E9-D9=0,"0",IF(E9-D9>0,"+","-")&IF(MOD(ABS(E9-D9),1)=0,TEXT(ABS(E9-D9),"0"),TEXT(ABS(E9-D9),"0.##")))) -> +1 | H9: D4 | I9: 更新与错误定位 | J9: 6 | K9: =IF(COUNTIFS(评分与用量!$A$2:$A$634,$B$2,评分与用量!$B$2:$B$634,"第一轮",评分与用量!$C$2:$C$634,"S分项",评分与用量!$J$2:$J$634,"D4")=0,"",SUMIFS(评分与用量!$E$2:$E$634,评分与用量!$A$2:$A$634,$B$2,评分与用量!$B$2:$B$634,"第一轮",评分与用量!$C$2:$C$634,"S分项",评分与用量!$J$2:$J$634,"D4")) -> 3 | L9: =IF(COUNTIFS(评分与用量!$A$2:$A$634,$B$2,评分与用量!$B$2:$B$634,"第二轮",评分与用量!$C$2:$C$634,"S分项",评分与用量!$J$2:$J$634,"D4")=0,"",SUMIFS(评分与用量!$E$2:$E$634,评分与用量!$A$2:$A$634,$B$2,评分与用量!$B$2:$B$634,"第二轮",评分与用量!$C$2:$C$634,"S分项",评分与用量!$J$2:$J$634,"D4")) -> 4.5 | M9: =IF(OR(K9="",L9=""),"",IF(L9-K9=0,"0",IF(L9-K9>0,"+","-")&IF(MOD(ABS(L9-K9),1)=0,TEXT(ABS(L9-K9),"0"),TEXT(ABS(L9-K9),"0.##")))) -> +1.5
A10: B 证据与计算 · 20分 | H10: D5 | I10: 原AI的成品检查 | J10: 3 | K10: =IF(COUNTIFS(评分与用量!$A$2:$A$634,$B$2,评分与用量!$B$2:$B$634,"第一轮",评分与用量!$C$2:$C$634,"S分项",评分与用量!$J$2:$J$634,"D5")=0,"",SUMIFS(评分与用量!$E$2:$E$634,评分与用量!$A$2:$A$634,$B$2,评分与用量!$B$2:$B$634,"第一轮",评分与用量!$C$2:$C$634,"S分项",评分与用量!$J$2:$J$634,"D5")) -> 2.25 | L10: =IF(COUNTIFS(评分与用量!$A$2:$A$634,$B$2,评分与用量!$B$2:$B$634,"第二轮",评分与用量!$C$2:$C$634,"S分项",评分与用量!$J$2:$J$634,"D5")=0,"",SUMIFS(评分与用量!$E$2:$E$634,评分与用量!$A$2:$A$634,$B$2,评分与用量!$B$2:$B$634,"第二轮",评分与用量!$C$2:$C$634,"S分项",评分与用量!$J$2:$J$634,"D5")) -> 3 | M10: =IF(OR(K10="",L10=""),"",IF(L10-K10=0,"0",IF(L10-K10>0,"+","-")&IF(MOD(ABS(L10-K10),1)=0,TEXT(ABS(L10-K10),"0"),TEXT(ABS(L10-K10),"0.##")))) -> +0.75
A11: B1 | B11: 数字与口径 | C11: 6 | D11: =IF(COUNTIFS(评分与用量!$A$2:$A$634,$B$2,评分与用量!$B$2:$B$634,"第一轮",评分与用量!$C$2:$C$634,"S分项",评分与用量!$J$2:$J$634,"B1")=0,"",SUMIFS(评分与用量!$E$2:$E$634,评分与用量!$A$2:$A$634,$B$2,评分与用量!$B$2:$B$634,"第一轮",评分与用量!$C$2:$C$634,"S分项",评分与用量!$J$2:$J$634,"B1")) -> 6 | E11: =IF(COUNTIFS(评分与用量!$A$2:$A$634,$B$2,评分与用量!$B$2:$B$634,"第二轮",评分与用量!$C$2:$C$634,"S分项",评分与用量!$J$2:$J$634,"B1")=0,"",SUMIFS(评分与用量!$E$2:$E$634,评分与用量!$A$2:$A$634,$B$2,评分与用量!$B$2:$B$634,"第二轮",评分与用量!$C$2:$C$634,"S分项",评分与用量!$J$2:$J$634,"B1")) -> 6 | F11: =IF(OR(D11="",E11=""),"",IF(E11-D11=0,"0",IF(E11-D11>0,"+","-")&IF(MOD(ABS(E11-D11),1)=0,TEXT(ABS(E11-D11),"0"),TEXT(ABS(E11-D11),"0.##")))) -> 0 | H11: E 成品实际可用性 · 10分
A12: B2 | B12: 可比性 | C12: 5 | D12: =IF(COUNTIFS(评分与用量!$A$2:$A$634,$B$2,评分与用量!$B$2:$B$634,"第一轮",评分与用量!$C$2:$C$634,"S分项",评分与用量!$J$2:$J$634,"B2")=0,"",SUMIFS(评分与用量!$E$2:$E$634,评分与用量!$A$2:$A$634,$B$2,评分与用量!$B$2:$B$634,"第一轮",评分与用量!$C$2:$C$634,"S分项",评分与用量!$J$2:$J$634,"B2")) -> 5 | E12: =IF(COUNTIFS(评分与用量!$A$2:$A$634,$B$2,评分与用量!$B$2:$B$634,"第二轮",评分与用量!$C$2:$C$634,"S分项",评分与用量!$J$2:$J$634,"B2")=0,"",SUMIFS(评分与用量!$E$2:$E$634,评分与用量!$A$2:$A$634,$B$2,评分与用量!$B$2:$B$634,"第二轮",评分与用量!$C$2:$C$634,"S分项",评分与用量!$J$2:$J$634,"B2")) -> 5 | F12: =IF(OR(D12="",E12=""),"",IF(E12-D12=0,"0",IF(E12-D12>0,"+","-")&IF(MOD(ABS(E12-D12),1)=0,TEXT(ABS(E12-D12),"0"),TEXT(ABS(E12-D12),"0.##")))) -> 0 | H12: E1 | I12: 阅读与比较 | J12: 4 | K12: =IF(COUNTIFS(评分与用量!$A$2:$A$634,$B$2,评分与用量!$B$2:$B$634,"第一轮",评分与用量!$C$2:$C$634,"S分项",评分与用量!$J$2:$J$634,"E1")=0,"",SUMIFS(评分与用量!$E$2:$E$634,评分与用量!$A$2:$A$634,$B$2,评分与用量!$B$2:$B$634,"第一轮",评分与用量!$C$2:$C$634,"S分项",评分与用量!$J$2:$J$634,"E1")) -> 4 | L12: =IF(COUNTIFS(评分与用量!$A$2:$A$634,$B$2,评分与用量!$B$2:$B$634,"第二轮",评分与用量!$C$2:$C$634,"S分项",评分与用量!$J$2:$J$634,"E1")=0,"",SUMIFS(评分与用量!$E$2:$E$634,评分与用量!$A$2:$A$634,$B$2,评分与用量!$B$2:$B$634,"第二轮",评分与用量!$C$2:$C$634,"S分项",评分与用量!$J$2:$J$634,"E1")) -> 4 | M12: =IF(OR(K12="",L12=""),"",IF(L12-K12=0,"0",IF(L12-K12>0,"+","-")&IF(MOD(ABS(L12-K12),1)=0,TEXT(ABS(L12-K12),"0"),TEXT(ABS(L12-K12),"0.##")))) -> 0
A13: B3 | B13: 来源链 | C13: 5 | D13: =IF(COUNTIFS(评分与用量!$A$2:$A$634,$B$2,评分与用量!$B$2:$B$634,"第一轮",评分与用量!$C$2:$C$634,"S分项",评分与用量!$J$2:$J$634,"B3")=0,"",SUMIFS(评分与用量!$E$2:$E$634,评分与用量!$A$2:$A$634,$B$2,评分与用量!$B$2:$B$634,"第一轮",评分与用量!$C$2:$C$634,"S分项",评分与用量!$J$2:$J$634,"B3")) -> 5 | E13: =IF(COUNTIFS(评分与用量!$A$2:$A$634,$B$2,评分与用量!$B$2:$B$634,"第二轮",评分与用量!$C$2:$C$634,"S分项",评分与用量!$J$2:$J$634,"B3")=0,"",SUMIFS(评分与用量!$E$2:$E$634,评分与用量!$A$2:$A$634,$B$2,评分与用量!$B$2:$B$634,"第二轮",评分与用量!$C$2:$C$634,"S分项",评分与用量!$J$2:$J$634,"B3")) -> 5 | F13: =IF(OR(D13="",E13=""),"",IF(E13-D13=0,"0",IF(E13-D13>0,"+","-")&IF(MOD(ABS(E13-D13),1)=0,TEXT(ABS(E13-D13),"0"),TEXT(ABS(E13-D13),"0.##")))) -> 0 | H13: E2 | I13: 画面与交互 | J13: 3 | K13: =IF(COUNTIFS(评分与用量!$A$2:$A$634,$B$2,评分与用量!$B$2:$B$634,"第一轮",评分与用量!$C$2:$C$634,"S分项",评分与用量!$J$2:$J$634,"E2")=0,"",SUMIFS(评分与用量!$E$2:$E$634,评分与用量!$A$2:$A$634,$B$2,评分与用量!$B$2:$B$634,"第一轮",评分与用量!$C$2:$C$634,"S分项",评分与用量!$J$2:$J$634,"E2")) -> 3 | L13: =IF(COUNTIFS(评分与用量!$A$2:$A$634,$B$2,评分与用量!$B$2:$B$634,"第二轮",评分与用量!$C$2:$C$634,"S分项",评分与用量!$J$2:$J$634,"E2")=0,"",SUMIFS(评分与用量!$E$2:$E$634,评分与用量!$A$2:$A$634,$B$2,评分与用量!$B$2:$B$634,"第二轮",评分与用量!$C$2:$C$634,"S分项",评分与用量!$J$2:$J$634,"E2")) -> 3 | M13: =IF(OR(K13="",L13=""),"",IF(L13-K13=0,"0",IF(L13-K13>0,"+","-")&IF(MOD(ABS(L13-K13),1)=0,TEXT(ABS(L13-K13),"0"),TEXT(ABS(L13-K13),"0.##")))) -> 0
A14: B4 | B14: 解释成立 | C14: 4 | D14: =IF(COUNTIFS(评分与用量!$A$2:$A$634,$B$2,评分与用量!$B$2:$B$634,"第一轮",评分与用量!$C$2:$C$634,"S分项",评分与用量!$J$2:$J$634,"B4")=0,"",SUMIFS(评分与用量!$E$2:$E$634,评分与用量!$A$2:$A$634,$B$2,评分与用量!$B$2:$B$634,"第一轮",评分与用量!$C$2:$C$634,"S分项",评分与用量!$J$2:$J$634,"B4")) -> 4 | E14: =IF(COUNTIFS(评分与用量!$A$2:$A$634,$B$2,评分与用量!$B$2:$B$634,"第二轮",评分与用量!$C$2:$C$634,"S分项",评分与用量!$J$2:$J$634,"B4")=0,"",SUMIFS(评分与用量!$E$2:$E$634,评分与用量!$A$2:$A$634,$B$2,评分与用量!$B$2:$B$634,"第二轮",评分与用量!$C$2:$C$634,"S分项",评分与用量!$J$2:$J$634,"B4")) -> 4 | F14: =IF(OR(D14="",E14=""),"",IF(E14-D14=0,"0",IF(E14-D14>0,"+","-")&IF(MOD(ABS(E14-D14),1)=0,TEXT(ABS(E14-D14),"0"),TEXT(ABS(E14-D14),"0.##")))) -> 0 | H14: E3 | I14: 文件一致与完成声明 | J14: 3 | K14: =IF(COUNTIFS(评分与用量!$A$2:$A$634,$B$2,评分与用量!$B$2:$B$634,"第一轮",评分与用量!$C$2:$C$634,"S分项",评分与用量!$J$2:$J$634,"E3")=0,"",SUMIFS(评分与用量!$E$2:$E$634,评分与用量!$A$2:$A$634,$B$2,评分与用量!$B$2:$B$634,"第一轮",评分与用量!$C$2:$C$634,"S分项",评分与用量!$J$2:$J$634,"E3")) -> 3 | L14: =IF(COUNTIFS(评分与用量!$A$2:$A$634,$B$2,评分与用量!$B$2:$B$634,"第二轮",评分与用量!$C$2:$C$634,"S分项",评分与用量!$J$2:$J$634,"E3")=0,"",SUMIFS(评分与用量!$E$2:$E$634,评分与用量!$A$2:$A$634,$B$2,评分与用量!$B$2:$B$634,"第二轮",评分与用量!$C$2:$C$634,"S分项",评分与用量!$J$2:$J$634,"E3")) -> 3 | M14: =IF(OR(K14="",L14=""),"",IF(L14-K14=0,"0",IF(L14-K14>0,"+","-")&IF(MOD(ABS(L14-K14),1)=0,TEXT(ABS(L14-K14),"0"),TEXT(ABS(L14-K14),"0.##")))) -> 0
A15: C 调查深度与判断 · 20分 | H15: F 自主性与资源纪律 · 10分
A16: C1 | B16: 差异分解 | C16: 4 | D16: =IF(COUNTIFS(评分与用量!$A$2:$A$634,$B$2,评分与用量!$B$2:$B$634,"第一轮",评分与用量!$C$2:$C$634,"S分项",评分与用量!$J$2:$J$634,"C1")=0,"",SUMIFS(评分与用量!$E$2:$E$634,评分与用量!$A$2:$A$634,$B$2,评分与用量!$B$2:$B$634,"第一轮",评分与用量!$C$2:$C$634,"S分项",评分与用量!$J$2:$J$634,"C1")) -> 4 | E16: =IF(COUNTIFS(评分与用量!$A$2:$A$634,$B$2,评分与用量!$B$2:$B$634,"第二轮",评分与用量!$C$2:$C$634,"S分项",评分与用量!$J$2:$J$634,"C1")=0,"",SUMIFS(评分与用量!$E$2:$E$634,评分与用量!$A$2:$A$634,$B$2,评分与用量!$B$2:$B$634,"第二轮",评分与用量!$C$2:$C$634,"S分项",评分与用量!$J$2:$J$634,"C1")) -> 4 | F16: =IF(OR(D16="",E16=""),"",IF(E16-D16=0,"0",IF(E16-D16>0,"+","-")&IF(MOD(ABS(E16-D16),1)=0,TEXT(ABS(E16-D16),"0"),TEXT(ABS(E16-D16),"0.##")))) -> 0 | H16: F1 | I16: 原运行独立性 | J16: 3 | K16: =IF(COUNTIFS(评分与用量!$A$2:$A$634,$B$2,评分与用量!$B$2:$B$634,"第一轮",评分与用量!$C$2:$C$634,"S分项",评分与用量!$J$2:$J$634,"F1")=0,"",SUMIFS(评分与用量!$E$2:$E$634,评分与用量!$A$2:$A$634,$B$2,评分与用量!$B$2:$B$634,"第一轮",评分与用量!$C$2:$C$634,"S分项",评分与用量!$J$2:$J$634,"F1")) -> 3 | L16: =IF(COUNTIFS(评分与用量!$A$2:$A$634,$B$2,评分与用量!$B$2:$B$634,"第二轮",评分与用量!$C$2:$C$634,"S分项",评分与用量!$J$2:$J$634,"F1")=0,"",SUMIFS(评分与用量!$E$2:$E$634,评分与用量!$A$2:$A$634,$B$2,评分与用量!$B$2:$B$634,"第二轮",评分与用量!$C$2:$C$634,"S分项",评分与用量!$J$2:$J$634,"F1")) -> 3 | M16: =IF(OR(K16="",L16=""),"",IF(L16-K16=0,"0",IF(L16-K16>0,"+","-")&IF(MOD(ABS(L16-K16),1)=0,TEXT(ABS(L16-K16),"0"),TEXT(ABS(L16-K16),"0.##")))) -> 0
A17: C2 | B17: 下钻调查 | C17: 4 | D17: =IF(COUNTIFS(评分与用量!$A$2:$A$634,$B$2,评分与用量!$B$2:$B$634,"第一轮",评分与用量!$C$2:$C$634,"S分项",评分与用量!$J$2:$J$634,"C2")=0,"",SUMIFS(评分与用量!$E$2:$E$634,评分与用量!$A$2:$A$634,$B$2,评分与用量!$B$2:$B$634,"第一轮",评分与用量!$C$2:$C$634,"S分项",评分与用量!$J$2:$J$634,"C2")) -> 2 | E17: =IF(COUNTIFS(评分与用量!$A$2:$A$634,$B$2,评分与用量!$B$2:$B$634,"第二轮",评分与用量!$C$2:$C$634,"S分项",评分与用量!$J$2:$J$634,"C2")=0,"",SUMIFS(评分与用量!$E$2:$E$634,评分与用量!$A$2:$A$634,$B$2,评分与用量!$B$2:$B$634,"第二轮",评分与用量!$C$2:$C$634,"S分项",评分与用量!$J$2:$J$634,"C2")) -> 4 | F17: =IF(OR(D17="",E17=""),"",IF(E17-D17=0,"0",IF(E17-D17>0,"+","-")&IF(MOD(ABS(E17-D17),1)=0,TEXT(ABS(E17-D17),"0"),TEXT(ABS(E17-D17),"0.##")))) -> +2 | H17: F2 | I17: 交后修正负担 | J17: 3 | K17: =IF(COUNTIFS(评分与用量!$A$2:$A$634,$B$2,评分与用量!$B$2:$B$634,"第一轮",评分与用量!$C$2:$C$634,"S分项",评分与用量!$J$2:$J$634,"F2")=0,"",SUMIFS(评分与用量!$E$2:$E$634,评分与用量!$A$2:$A$634,$B$2,评分与用量!$B$2:$B$634,"第一轮",评分与用量!$C$2:$C$634,"S分项",评分与用量!$J$2:$J$634,"F2")) -> 3 | L17: =IF(COUNTIFS(评分与用量!$A$2:$A$634,$B$2,评分与用量!$B$2:$B$634,"第二轮",评分与用量!$C$2:$C$634,"S分项",评分与用量!$J$2:$J$634,"F2")=0,"",SUMIFS(评分与用量!$E$2:$E$634,评分与用量!$A$2:$A$634,$B$2,评分与用量!$B$2:$B$634,"第二轮",评分与用量!$C$2:$C$634,"S分项",评分与用量!$J$2:$J$634,"F2")) -> 3 | M17: =IF(OR(K17="",L17=""),"",IF(L17-K17=0,"0",IF(L17-K17>0,"+","-")&IF(MOD(ABS(L17-K17),1)=0,TEXT(ABS(L17-K17),"0"),TEXT(ABS(L17-K17),"0.##")))) -> 0
A18: C3 | B18: 稳健性与替代解释 | C18: 5 | D18: =IF(COUNTIFS(评分与用量!$A$2:$A$634,$B$2,评分与用量!$B$2:$B$634,"第一轮",评分与用量!$C$2:$C$634,"S分项",评分与用量!$J$2:$J$634,"C3")=0,"",SUMIFS(评分与用量!$E$2:$E$634,评分与用量!$A$2:$A$634,$B$2,评分与用量!$B$2:$B$634,"第一轮",评分与用量!$C$2:$C$634,"S分项",评分与用量!$J$2:$J$634,"C3")) -> 1.25 | E18: =IF(COUNTIFS(评分与用量!$A$2:$A$634,$B$2,评分与用量!$B$2:$B$634,"第二轮",评分与用量!$C$2:$C$634,"S分项",评分与用量!$J$2:$J$634,"C3")=0,"",SUMIFS(评分与用量!$E$2:$E$634,评分与用量!$A$2:$A$634,$B$2,评分与用量!$B$2:$B$634,"第二轮",评分与用量!$C$2:$C$634,"S分项",评分与用量!$J$2:$J$634,"C3")) -> 5 | F18: =IF(OR(D18="",E18=""),"",IF(E18-D18=0,"0",IF(E18-D18>0,"+","-")&IF(MOD(ABS(E18-D18),1)=0,TEXT(ABS(E18-D18),"0"),TEXT(ABS(E18-D18),"0.##")))) -> +3.75 | H18: F3 | I18: 失败处理 | J18: 2 | K18: =IF(COUNTIFS(评分与用量!$A$2:$A$634,$B$2,评分与用量!$B$2:$B$634,"第一轮",评分与用量!$C$2:$C$634,"S分项",评分与用量!$J$2:$J$634,"F3")=0,"",SUMIFS(评分与用量!$E$2:$E$634,评分与用量!$A$2:$A$634,$B$2,评分与用量!$B$2:$B$634,"第一轮",评分与用量!$C$2:$C$634,"S分项",评分与用量!$J$2:$J$634,"F3")) -> 2 | L18: =IF(COUNTIFS(评分与用量!$A$2:$A$634,$B$2,评分与用量!$B$2:$B$634,"第二轮",评分与用量!$C$2:$C$634,"S分项",评分与用量!$J$2:$J$634,"F3")=0,"",SUMIFS(评分与用量!$E$2:$E$634,评分与用量!$A$2:$A$634,$B$2,评分与用量!$B$2:$B$634,"第二轮",评分与用量!$C$2:$C$634,"S分项",评分与用量!$J$2:$J$634,"F3")) -> 2 | M18: =IF(OR(K18="",L18=""),"",IF(L18-K18=0,"0",IF(L18-K18>0,"+","-")&IF(MOD(ABS(L18-K18),1)=0,TEXT(ABS(L18-K18),"0"),TEXT(ABS(L18-K18),"0.##")))) -> 0
A19: C4 | B19: 据证据修正 | C19: 4 | D19: =IF(COUNTIFS(评分与用量!$A$2:$A$634,$B$2,评分与用量!$B$2:$B$634,"第一轮",评分与用量!$C$2:$C$634,"S分项",评分与用量!$J$2:$J$634,"C4")=0,"",SUMIFS(评分与用量!$E$2:$E$634,评分与用量!$A$2:$A$634,$B$2,评分与用量!$B$2:$B$634,"第一轮",评分与用量!$C$2:$C$634,"S分项",评分与用量!$J$2:$J$634,"C4")) -> 4 | E19: =IF(COUNTIFS(评分与用量!$A$2:$A$634,$B$2,评分与用量!$B$2:$B$634,"第二轮",评分与用量!$C$2:$C$634,"S分项",评分与用量!$J$2:$J$634,"C4")=0,"",SUMIFS(评分与用量!$E$2:$E$634,评分与用量!$A$2:$A$634,$B$2,评分与用量!$B$2:$B$634,"第二轮",评分与用量!$C$2:$C$634,"S分项",评分与用量!$J$2:$J$634,"C4")) -> 4 | F19: =IF(OR(D19="",E19=""),"",IF(E19-D19=0,"0",IF(E19-D19>0,"+","-")&IF(MOD(ABS(E19-D19),1)=0,TEXT(ABS(E19-D19),"0"),TEXT(ABS(E19-D19),"0.##")))) -> 0 | H19: F4 | I19: 资源使用 | J19: 2 | K19: =IF(COUNTIFS(评分与用量!$A$2:$A$634,$B$2,评分与用量!$B$2:$B$634,"第一轮",评分与用量!$C$2:$C$634,"S分项",评分与用量!$J$2:$J$634,"F4")=0,"",SUMIFS(评分与用量!$E$2:$E$634,评分与用量!$A$2:$A$634,$B$2,评分与用量!$B$2:$B$634,"第一轮",评分与用量!$C$2:$C$634,"S分项",评分与用量!$J$2:$J$634,"F4")) -> 2 | L19: =IF(COUNTIFS(评分与用量!$A$2:$A$634,$B$2,评分与用量!$B$2:$B$634,"第二轮",评分与用量!$C$2:$C$634,"S分项",评分与用量!$J$2:$J$634,"F4")=0,"",SUMIFS(评分与用量!$E$2:$E$634,评分与用量!$A$2:$A$634,$B$2,评分与用量!$B$2:$B$634,"第二轮",评分与用量!$C$2:$C$634,"S分项",评分与用量!$J$2:$J$634,"F4")) -> 2 | M19: =IF(OR(K19="",L19=""),"",IF(L19-K19=0,"0",IF(L19-K19>0,"+","-")&IF(MOD(ABS(L19-K19),1)=0,TEXT(ABS(L19-K19),"0"),TEXT(ABS(L19-K19),"0.##")))) -> 0
A20: C5 | B20: 范围与停止 | C20: 3 | D20: =IF(COUNTIFS(评分与用量!$A$2:$A$634,$B$2,评分与用量!$B$2:$B$634,"第一轮",评分与用量!$C$2:$C$634,"S分项",评分与用量!$J$2:$J$634,"C5")=0,"",SUMIFS(评分与用量!$E$2:$E$634,评分与用量!$A$2:$A$634,$B$2,评分与用量!$B$2:$B$634,"第一轮",评分与用量!$C$2:$C$634,"S分项",评分与用量!$J$2:$J$634,"C5")) -> 3 | E20: =IF(COUNTIFS(评分与用量!$A$2:$A$634,$B$2,评分与用量!$B$2:$B$634,"第二轮",评分与用量!$C$2:$C$634,"S分项",评分与用量!$J$2:$J$634,"C5")=0,"",SUMIFS(评分与用量!$E$2:$E$634,评分与用量!$A$2:$A$634,$B$2,评分与用量!$B$2:$B$634,"第二轮",评分与用量!$C$2:$C$634,"S分项",评分与用量!$J$2:$J$634,"C5")) -> 3 | F20: =IF(OR(D20="",E20=""),"",IF(E20-D20=0,"0",IF(E20-D20>0,"+","-")&IF(MOD(ABS(E20-D20),1)=0,TEXT(ABS(E20-D20),"0"),TEXT(ABS(E20-D20),"0.##")))) -> 0
A22: 现行 S /100 | C22: 100 | D22: =IF(COUNTIFS(评分与用量!$A$2:$A$634,$B$2,评分与用量!$B$2:$B$634,"第一轮",评分与用量!$C$2:$C$634,"S分项")=0,"",SUMIFS(评分与用量!$E$2:$E$634,评分与用量!$A$2:$A$634,$B$2,评分与用量!$B$2:$B$634,"第一轮",评分与用量!$C$2:$C$634,"S分项")) -> 88 | E22: =IF(COUNTIFS(评分与用量!$A$2:$A$634,$B$2,评分与用量!$B$2:$B$634,"第二轮",评分与用量!$C$2:$C$634,"S分项")=0,"",SUMIFS(评分与用量!$E$2:$E$634,评分与用量!$A$2:$A$634,$B$2,评分与用量!$B$2:$B$634,"第二轮",评分与用量!$C$2:$C$634,"S分项")) -> 98.5 | F22: =IF(OR(D22="",E22=""),"",IF(E22-D22=0,"0",IF(E22-D22>0,"+","-")&IF(MOD(ABS(E22-D22),1)=0,TEXT(ABS(E22-D22),"0"),TEXT(ABS(E22-D22),"0.##")))) -> +10.5 | H22: 已评分条款 | J22: 25 | K22: =IF(COUNTIFS(评分与用量!$A$2:$A$634,$B$2,评分与用量!$B$2:$B$634,"第一轮",评分与用量!$C$2:$C$634,"S分项")=0,"",COUNTIFS(评分与用量!$A$2:$A$634,$B$2,评分与用量!$B$2:$B$634,"第一轮",评分与用量!$C$2:$C$634,"S分项")) -> 25 | L22: =IF(COUNTIFS(评分与用量!$A$2:$A$634,$B$2,评分与用量!$B$2:$B$634,"第二轮",评分与用量!$C$2:$C$634,"S分项")=0,"",COUNTIFS(评分与用量!$A$2:$A$634,$B$2,评分与用量!$B$2:$B$634,"第二轮",评分与用量!$C$2:$C$634,"S分项")) -> 25 | M22: =IF(OR(K22="",L22=""),"",IF(L22-K22=0,"0",IF(L22-K22>0,"+","-")&IF(MOD(ABS(L22-K22),1)=0,TEXT(ABS(L22-K22),"0"),TEXT(ABS(L22-K22),"0.##")))) -> 0
A24: 空白表示该轮未评分；评分依据见“评分与用量”的 S 分项。

Sheet 单AI分析
B1: 单个 AI 评测明细 | R1: 返回评测总览 ›
B2: NYC311 自主交付评测 · 模型、宿主与当轮条件共同构成比较单位 | AA2: =IF(COUNTIFS(评分与用量!$A$2:$A$634,$C$3,评分与用量!$B$2:$B$634,$G$3,评分与用量!$C$2:$C$634,"S分项")=0,"",SUMIFS(评分与用量!$E$2:$E$634,评分与用量!$A$2:$A$634,$C$3,评分与用量!$B$2:$B$634,$G$3,评分与用量!$C$2:$C$634,"S分项")) -> 98.5 | AB2: =IF(COUNTIFS(评分与用量!$A$2:$A$634,$C$3,评分与用量!$B$2:$B$634,IF($G$3="第一轮","第二轮","第一轮"),评分与用量!$C$2:$C$634,"S分项")=0,"",SUMIFS(评分与用量!$E$2:$E$634,评分与用量!$A$2:$A$634,$C$3,评分与用量!$B$2:$B$634,IF($G$3="第一轮","第二轮","第一轮"),评分与用量!$C$2:$C$634,"S分项")) -> 88
B3: AI | C3: GPT | E3: ▼ | F3: 轮次 | G3: 第二轮 | I3: ▼ | J3: =IF(COUNTIFS(运行记录!$A$2:$A$16,$C$3,运行记录!$B$2:$B$16,$G$3)=0,"未运行",INDEX(运行记录!$E$2:$E$16,SUMPRODUCT((运行记录!$A$2:$A$16=$C$3)*(运行记录!$B$2:$B$16=$G$3)*(ROW(运行记录!$A$2:$A$16)-1))))&" · "&IF(COUNTIFS(运行记录!$A$2:$A$16,$C$3,运行记录!$B$2:$B$16,$G$3)=0,"未运行",INDEX(运行记录!$C$2:$C$16,SUMPRODUCT((运行记录!$A$2:$A$16=$C$3)*(运行记录!$B$2:$B$16=$G$3)*(ROW(运行记录!$A$2:$A$16)-1)))) -> Codex · 已完成 | AA3: =IF(SUMPRODUCT((运行记录!$A$2:$A$16=$C$3)*(运行记录!$B$2:$B$16=$G$3)*ISNUMBER(运行记录!$Q$2:$Q$16))=0,"",SUMIFS(运行记录!$Q$2:$Q$16,运行记录!$A$2:$A$16,$C$3,运行记录!$B$2:$B$16,$G$3)) -> 38.958408 | AB3: =IF(SUMPRODUCT((运行记录!$A$2:$A$16=$C$3)*(运行记录!$B$2:$B$16=$G$3)*ISNUMBER(运行记录!$R$2:$R$16))=0,"",SUMIFS(运行记录!$R$2:$R$16,运行记录!$A$2:$A$16,$C$3,运行记录!$B$2:$B$16,$G$3)) -> 38.958408
B4: 本轮现行 S | E4: 另一轮 S | H4: 耗时（分钟） | K4: API目录价（元） | N4: 总 Token | Q4: AWR | T4: 首交修正任务
B5: =IF(AA2="","—",AA2) -> 98.5 | E5: =IF(AB2="","—",AB2) -> 88 | H5: =IF(SUMPRODUCT((运行记录!$A$2:$A$16=$C$3)*(运行记录!$B$2:$B$16=$G$3)*ISNUMBER(运行记录!$M$2:$M$16))=0,"—",SUMIFS(运行记录!$M$2:$M$16,运行记录!$A$2:$A$16,$C$3,运行记录!$B$2:$B$16,$G$3)) -> 17.7814 | K5: =IF(OR(AA3="",AB3=""),"—",IF(ABS(AA3-AB3)<0.005,TEXT(AA3,"0.00"),TEXT(AA3,"0.00")&"–"&TEXT(AB3,"0.00"))) -> 38.96 | N5: =IF(SUMPRODUCT((运行记录!$A$2:$A$16=$C$3)*(运行记录!$B$2:$B$16=$G$3)*ISNUMBER(运行记录!$P$2:$P$16))=0,"",SUMIFS(运行记录!$P$2:$P$16,运行记录!$A$2:$A$16,$C$3,运行记录!$B$2:$B$16,$G$3)) -> 3244918 | Q5: =IF(COUNTIFS(行为记录!$A$2:$A$816,$C$3,行为记录!$B$2:$B$816,$G$3,行为记录!$L$2:$L$816,"<>管理动作")=0,"",COUNTIFS(行为记录!$A$2:$A$816,$C$3,行为记录!$B$2:$B$816,$G$3,行为记录!$L$2:$L$816,"确认无收益")/(COUNTIFS(行为记录!$A$2:$A$816,$C$3,行为记录!$B$2:$B$816,$G$3,行为记录!$L$2:$L$816,"直接贡献交付")+COUNTIFS(行为记录!$A$2:$A$816,$C$3,行为记录!$B$2:$B$816,$G$3,行为记录!$L$2:$L$816,"必要探索")+COUNTIFS(行为记录!$A$2:$A$816,$C$3,行为记录!$B$2:$B$816,$G$3,行为记录!$L$2:$L$816,"确认无收益"))) -> 0.0625 | T5: =IF(COUNTIFS(评分与用量!$A$2:$A$623,$C$3,评分与用量!$B$2:$B$623,$G$3,评分与用量!$C$2:$C$623,"人工负担证据",评分与用量!$D$2:$D$623,"首交后需处理任务数")=0,"",SUMIFS(评分与用量!$E$2:$E$623,评分与用量!$A$2:$A$623,$C$3,评分与用量!$B$2:$B$623,$G$3,评分与用量!$C$2:$C$623,"人工负担证据",评分与用量!$D$2:$D$623,"首交后需处理任务数")) -> 0
AA7: 数据基础与问题定义 | AB7: =IF(COUNTIFS(评分与用量!$A$2:$A$634,$C$3,评分与用量!$B$2:$B$634,"第一轮",评分与用量!$C$2:$C$634,"S分项",评分与用量!$J$2:$J$634,"A*")=0,NA(),SUMIFS(评分与用量!$E$2:$E$634,评分与用量!$A$2:$A$634,$C$3,评分与用量!$B$2:$B$634,"第一轮",评分与用量!$C$2:$C$634,"S分项",评分与用量!$J$2:$J$634,"A*")/15) -> 0.93333333 | AD7: 数据基础与问题定义 | AE7: =IF(COUNTIFS(评分与用量!$A$2:$A$634,$C$3,评分与用量!$B$2:$B$634,"第二轮",评分与用量!$C$2:$C$634,"S分项",评分与用量!$J$2:$J$634,"A*")=0,NA(),SUMIFS(评分与用量!$E$2:$E$634,评分与用量!$A$2:$A$634,$C$3,评分与用量!$B$2:$B$634,"第二轮",评分与用量!$C$2:$C$634,"S分项",评分与用量!$J$2:$J$634,"A*")/15) -> 1
R8: 六维 S 评分 | AA8: 证据与计算 | AB8: =IF(COUNTIFS(评分与用量!$A$2:$A$634,$C$3,评分与用量!$B$2:$B$634,"第一轮",评分与用量!$C$2:$C$634,"S分项",评分与用量!$J$2:$J$634,"B*")=0,NA(),SUMIFS(评分与用量!$E$2:$E$634,评分与用量!$A$2:$A$634,$C$3,评分与用量!$B$2:$B$634,"第一轮",评分与用量!$C$2:$C$634,"S分项",评分与用量!$J$2:$J$634,"B*")/20) -> 1 | AD8: 证据与计算 | AE8: =IF(COUNTIFS(评分与用量!$A$2:$A$634,$C$3,评分与用量!$B$2:$B$634,"第二轮",评分与用量!$C$2:$C$634,"S分项",评分与用量!$J$2:$J$634,"B*")=0,NA(),SUMIFS(评分与用量!$E$2:$E$634,评分与用量!$A$2:$A$634,$C$3,评分与用量!$B$2:$B$634,"第二轮",评分与用量!$C$2:$C$634,"S分项",评分与用量!$J$2:$J$634,"B*")/20) -> 1 | AH8: Token 构成
R9: 现行 S | T9: 满分均为 100 | AA9: 调查深度与判断 | AB9: =IF(COUNTIFS(评分与用量!$A$2:$A$634,$C$3,评分与用量!$B$2:$B$634,"第一轮",评分与用量!$C$2:$C$634,"S分项",评分与用量!$J$2:$J$634,"C*")=0,NA(),SUMIFS(评分与用量!$E$2:$E$634,评分与用量!$A$2:$A$634,$C$3,评分与用量!$B$2:$B$634,"第一轮",评分与用量!$C$2:$C$634,"S分项",评分与用量!$J$2:$J$634,"C*")/20) -> 0.7125 | AD9: 调查深度与判断 | AE9: =IF(COUNTIFS(评分与用量!$A$2:$A$634,$C$3,评分与用量!$B$2:$B$634,"第二轮",评分与用量!$C$2:$C$634,"S分项",评分与用量!$J$2:$J$634,"C*")=0,NA(),SUMIFS(评分与用量!$E$2:$E$634,评分与用量!$A$2:$A$634,$C$3,评分与用量!$B$2:$B$634,"第二轮",评分与用量!$C$2:$C$634,"S分项",评分与用量!$J$2:$J$634,"C*")/20) -> 1 | AH9: 未缓存输入 | AK9: =IF(COUNTIFS(评分与用量!$A$2:$A$623,$C$3,评分与用量!$B$2:$B$623,$G$3,评分与用量!$C$2:$C$623,"Token用量",评分与用量!$D$2:$D$623,"未缓存输入Token")=0,"",SUMIFS(评分与用量!$E$2:$E$623,评分与用量!$A$2:$A$623,$C$3,评分与用量!$B$2:$B$623,$G$3,评分与用量!$C$2:$C$623,"Token用量",评分与用量!$D$2:$D$623,"未缓存输入Token")) -> 142815
R10: AWR | T10: 不含管理动作 | AA10: 人工复现与维护 | AB10: =IF(COUNTIFS(评分与用量!$A$2:$A$634,$C$3,评分与用量!$B$2:$B$634,"第一轮",评分与用量!$C$2:$C$634,"S分项",评分与用量!$J$2:$J$634,"D*")=0,NA(),SUMIFS(评分与用量!$E$2:$E$634,评分与用量!$A$2:$A$634,$C$3,评分与用量!$B$2:$B$634,"第一轮",评分与用量!$C$2:$C$634,"S分项",评分与用量!$J$2:$J$634,"D*")/25) -> 0.79 | AD10: 人工复现与维护 | AE10: =IF(COUNTIFS(评分与用量!$A$2:$A$634,$C$3,评分与用量!$B$2:$B$634,"第二轮",评分与用量!$C$2:$C$634,"S分项",评分与用量!$J$2:$J$634,"D*")=0,NA(),SUMIFS(评分与用量!$E$2:$E$634,评分与用量!$A$2:$A$634,$C$3,评分与用量!$B$2:$B$634,"第二轮",评分与用量!$C$2:$C$634,"S分项",评分与用量!$J$2:$J$634,"D*")/25) -> 0.94 | AH10: 缓存读取 | AK10: =IF(COUNTIFS(评分与用量!$A$2:$A$623,$C$3,评分与用量!$B$2:$B$623,$G$3,评分与用量!$C$2:$C$623,"Token用量",评分与用量!$D$2:$D$623,"缓存读取Token")=0,"",SUMIFS(评分与用量!$E$2:$E$623,评分与用量!$A$2:$A$623,$C$3,评分与用量!$B$2:$B$623,$G$3,评分与用量!$C$2:$C$623,"Token用量",评分与用量!$D$2:$D$623,"缓存读取Token")) -> 3076992
R11: 目录价 | T11: 供成本比较，非实际账单 | AA11: 成品实际可用性 | AB11: =IF(COUNTIFS(评分与用量!$A$2:$A$634,$C$3,评分与用量!$B$2:$B$634,"第一轮",评分与用量!$C$2:$C$634,"S分项",评分与用量!$J$2:$J$634,"E*")=0,NA(),SUMIFS(评分与用量!$E$2:$E$634,评分与用量!$A$2:$A$634,$C$3,评分与用量!$B$2:$B$634,"第一轮",评分与用量!$C$2:$C$634,"S分项",评分与用量!$J$2:$J$634,"E*")/10) -> 1 | AD11: 成品实际可用性 | AE11: =IF(COUNTIFS(评分与用量!$A$2:$A$634,$C$3,评分与用量!$B$2:$B$634,"第二轮",评分与用量!$C$2:$C$634,"S分项",评分与用量!$J$2:$J$634,"E*")=0,NA(),SUMIFS(评分与用量!$E$2:$E$634,评分与用量!$A$2:$A$634,$C$3,评分与用量!$B$2:$B$634,"第二轮",评分与用量!$C$2:$C$634,"S分项",评分与用量!$J$2:$J$634,"E*")/10) -> 1 | AH11: 缓存写入 | AK11: =IF(COUNTIFS(评分与用量!$A$2:$A$623,$C$3,评分与用量!$B$2:$B$623,$G$3,评分与用量!$C$2:$C$623,"Token用量",评分与用量!$D$2:$D$623,"缓存写入Token")=0,"",SUMIFS(评分与用量!$E$2:$E$623,评分与用量!$A$2:$A$623,$C$3,评分与用量!$B$2:$B$623,$G$3,评分与用量!$C$2:$C$623,"Token用量",评分与用量!$D$2:$D$623,"缓存写入Token")) -> 0
R12: 缺失值 | T12: 保留空白或“—” | AA12: 自主性与资源纪律 | AB12: =IF(COUNTIFS(评分与用量!$A$2:$A$634,$C$3,评分与用量!$B$2:$B$634,"第一轮",评分与用量!$C$2:$C$634,"S分项",评分与用量!$J$2:$J$634,"F*")=0,NA(),SUMIFS(评分与用量!$E$2:$E$634,评分与用量!$A$2:$A$634,$C$3,评分与用量!$B$2:$B$634,"第一轮",评分与用量!$C$2:$C$634,"S分项",评分与用量!$J$2:$J$634,"F*")/10) -> 1 | AD12: 自主性与资源纪律 | AE12: =IF(COUNTIFS(评分与用量!$A$2:$A$634,$C$3,评分与用量!$B$2:$B$634,"第二轮",评分与用量!$C$2:$C$634,"S分项",评分与用量!$J$2:$J$634,"F*")=0,NA(),SUMIFS(评分与用量!$E$2:$E$634,评分与用量!$A$2:$A$634,$C$3,评分与用量!$B$2:$B$634,"第二轮",评分与用量!$C$2:$C$634,"S分项",评分与用量!$J$2:$J$634,"F*")/10) -> 1 | AH12: 输出 | AK12: =IF(COUNTIFS(评分与用量!$A$2:$A$623,$C$3,评分与用量!$B$2:$B$623,$G$3,评分与用量!$C$2:$C$623,"Token用量",评分与用量!$D$2:$D$623,"输出Token")=0,"",SUMIFS(评分与用量!$E$2:$E$623,评分与用量!$A$2:$A$623,$C$3,评分与用量!$B$2:$B$623,$G$3,评分与用量!$C$2:$C$623,"Token用量",评分与用量!$D$2:$D$623,"输出Token")) -> 25111
R14: 本轮资格 | AH14: 动作构成
R15: =IF(C3="Claude",IF(G3="第一轮","仅第一轮混合成品中可归属Claude的工作评分；接续工作不倒填。","未运行，评分留空。"),IF(C3="Kimi","未形成完整交付，评分留空。","六系统配对评分。")) -> 六系统配对评分。 | AH15: 直接贡献交付 | AK15: =IF(COUNTIFS(行为记录!$A$2:$A$816,$C$3,行为记录!$B$2:$B$816,$G$3)=0,"",COUNTIFS(行为记录!$A$2:$A$816,$C$3,行为记录!$B$2:$B$816,$G$3,行为记录!$L$2:$L$816,"直接贡献交付")) -> 20
AH16: 必要探索 | AK16: =IF(COUNTIFS(行为记录!$A$2:$A$816,$C$3,行为记录!$B$2:$B$816,$G$3)=0,"",COUNTIFS(行为记录!$A$2:$A$816,$C$3,行为记录!$B$2:$B$816,$G$3,行为记录!$L$2:$L$816,"必要探索")) -> 10
R17: 评分细项：下拉切换 AI，查看两轮25项评分。 评分与用量：查分项及依据编号。 | AH17: 管理动作 | AK17: =IF(COUNTIFS(行为记录!$A$2:$A$816,$C$3,行为记录!$B$2:$B$816,$G$3)=0,"",COUNTIFS(行为记录!$A$2:$A$816,$C$3,行为记录!$B$2:$B$816,$G$3,行为记录!$L$2:$L$816,"管理动作")) -> 4
B18: =IF(COUNT($AB$7:$AB$11)=0,"暂无分项记录","最低分项得分率 · "&INDEX($AA$7:$AA$11,MATCH(MIN($AB$7:$AB$11),$AB$7:$AB$11,0))&" "&TEXT(MIN($AB$7:$AB$11),"0%")) -> 最低分项得分率 · 调查深度与判断 71% | J18: =IF(COUNT($AE$7:$AE$11)=0,"暂无分项记录","最低分项得分率 · "&INDEX($AD$7:$AD$11,MATCH(MIN($AE$7:$AE$11),$AE$7:$AE$11,0))&" "&TEXT(MIN($AE$7:$AE$11),"0%")) -> 最低分项得分率 · 人工复现与维护 94% | AH18: 确认无收益 | AK18: =IF(COUNTIFS(行为记录!$A$2:$A$816,$C$3,行为记录!$B$2:$B$816,$G$3)=0,"",COUNTIFS(行为记录!$A$2:$A$816,$C$3,行为记录!$B$2:$B$816,$G$3,行为记录!$L$2:$L$816,"确认无收益")) -> 2
B20: 两轮变化
B21: 指标 | D21: 第一轮 | I21: 第二轮 | M21: 变化
